File: BEAM 2.1.csv
No.,Time,Load,Disp,Strength,Strain
,[sec],[kN],[mm],[kN/mm²],[%]
1,0,0,0,0,0
39,2.541,0.37,0.027,0.001,0
77,5.151,0.53,0.05,0.001,0
115,7.053,0.69,0.073,0.002,0.001
153,8.707,0.85,0.098,0.002,0.001
191,10.237,1,0.124,0.002,0.001
229,11.516,1.18,0.148,0.003,0.001
267,12.623,1.35,0.17,0.003,0.001
305,13.722,1.52,0.193,0.003,0.002
343,14.739,1.7,0.215,0.004,0.002
381,15.726,1.87,0.237,0.004,0.002
419,16.685,2.04,0.259,0.005,0.002
457,17.57,2.2,0.281,0.005,0.002
495,18.458,2.36,0.302,0.005,0.002
533,19.3,2.53,0.323,0.006,0.003
571,20.202,2.71,0.347,0.006,0.003
609,21.074,2.89,0.369,0.006,0.003
647,21.94,3.07,0.392,0.007,0.003
685,22.773,3.24,0.415,0.007,0.003
723,23.646,3.42,0.439,0.008,0.004
761,24.478,3.59,0.462,0.008,0.004
799,25.342,3.77,0.486,0.008,0.004
837,26.143,3.93,0.509,0.009,0.004
875,26.952,4.09,0.532,0.009,0.004
913,27.704,4.25,0.555,0.009,0.005
951,28.484,4.42,0.578,0.01,0.005
989,29.298,4.57,0.603,0.01,0.005
1027,30.078,4.73,0.627,0.011,0.005
1065,30.851,4.89,0.651,0.011,0.005
1103,31.636,5.05,0.676,0.011,0.006
1141,32.372,5.22,0.699,0.012,0.006
1179,33.102,5.39,0.723,0.012,0.006
1217,33.81,5.56,0.746,0.012,0.006
1255,34.534,5.75,0.769,0.013,0.006
1293,35.228,5.92,0.792,0.013,0.007
1331,35.934,6.1,0.814,0.014,0.007
1369,36.614,6.29,0.837,0.014,0.007
1407,37.316,6.48,0.86,0.014,0.007
1445,38.016,6.66,0.883,0.015,0.007
1483,38.682,6.85,0.904,0.015,0.007
1521,39.309,7.02,0.925,0.016,0.008
1559,39.978,7.2,0.947,0.016,0.008
1597,40.65,7.38,0.969,0.016,0.008
1635,41.314,7.56,0.99,0.017,0.008
1673,41.998,7.74,1.013,0.017,0.008
1711,42.674,7.92,1.035,0.018,0.009
1749,43.348,8.1,1.057,0.018,0.009
1787,44.038,8.29,1.079,0.018,0.009
1825,44.749,8.48,1.102,0.019,0.009
1863,45.429,8.65,1.124,0.019,0.009
1901,46.136,8.84,1.148,0.02,0.009
1939,46.813,9.03,1.17,0.02,0.01
1977,47.486,9.21,1.192,0.02,0.01
2015,48.189,9.39,1.215,0.021,0.01
2053,48.833,9.57,1.236,0.021,0.01
2091,49.538,9.75,1.259,0.022,0.01
2129,50.224,9.94,1.281,0.022,0.011
2167,50.897,10.12,1.303,0.022,0.011
2205,51.562,10.29,1.325,0.023,0.011
2243,52.266,10.48,1.347,0.023,0.011
2281,52.917,10.66,1.369,0.024,0.011
2319,53.631,10.85,1.392,0.024,0.011
2357,54.313,11.03,1.414,0.025,0.012
2395,55.007,11.2,1.437,0.025,0.012
2433,55.711,11.38,1.46,0.025,0.012
2471,56.443,11.56,1.484,0.026,0.012
2509,57.145,11.74,1.507,0.026,0.012
2547,57.889,11.93,1.531,0.027,0.013
2585,58.661,12.11,1.557,0.027,0.013
2623,59.365,12.27,1.58,0.027,0.013
2661,60.125,12.4,1.605,0.028,0.013
2699,60.845,12.55,1.63,0.028,0.013
2737,61.553,12.69,1.655,0.028,0.014
2775,62.325,12.83,1.682,0.029,0.014
2813,63.052,12.96,1.708,0.029,0.014
2851,63.757,13.1,1.733,0.029,0.014
2889,64.489,13.23,1.76,0.029,0.014
2927,65.249,13.33,1.788,0.03,0.015
2965,66.127,13.36,1.822,0.03,0.015
3003,66.929,13.44,1.854,0.03,0.015
3041,67.685,13.52,1.885,0.03,0.016
3079,68.445,13.57,1.917,0.03,0.016
3117,69.197,13.61,1.949,0.03,0.016
3155,69.889,13.68,1.981,0.03,0.016
3193,70.589,13.74,2.013,0.031,0.017
3231,71.313,13.8,2.047,0.031,0.017
3269,72.017,13.85,2.081,0.031,0.017
3307,72.705,13.89,2.115,0.031,0.017
3345,73.417,13.95,2.151,0.031,0.018
3383,74.056,14,2.184,0.031,0.018
3421,74.696,14.04,2.217,0.031,0.018
3459,75.328,14.08,2.252,0.031,0.019
3497,75.98,14.1,2.288,0.031,0.019
3535,76.63,14.11,2.324,0.031,0.019
3573,77.248,14.08,2.36,0.031,0.019
3611,77.871,14.08,2.398,0.031,0.02
3649,78.472,14.07,2.435,0.031,0.02
3687,79.061,14.08,2.472,0.031,0.02
3725,79.641,14.09,2.509,0.031,0.021
3763,80.188,14.07,2.545,0.031,0.021
3801,80.741,14.06,2.582,0.031,0.021
3839,81.298,14.06,2.62,0.031,0.022
3877,81.841,14.06,2.658,0.031,0.022
3915,82.378,14.06,2.696,0.031,0.022
3953,82.888,14.07,2.733,0.031,0.022
3991,83.408,14.07,2.771,0.031,0.023
4029,83.917,14.07,2.809,0.031,0.023
4067,84.417,14.07,2.847,0.031,0.023
4105,84.908,14.06,2.885,0.031,0.024
4143,85.379,14.07,2.922,0.031,0.024
4181,85.853,14.07,2.959,0.031,0.024
4219,86.324,14.07,2.998,0.031,0.025
4257,86.776,14.06,3.034,0.031,0.025
4295,87.214,14.04,3.071,0.031,0.025
4333,87.624,14.01,3.106,0.031,0.026
4371,88.068,14.01,3.144,0.031,0.026
4409,88.497,14,3.181,0.031,0.026
4447,88.916,14.01,3.218,0.031,0.026
4485,89.344,14.01,3.256,0.031,0.027
4523,89.766,14.01,3.294,0.031,0.027
4561,90.172,14,3.331,0.031,0.027
4599,90.584,14,3.369,0.031,0.028
4637,90.992,14,3.407,0.031,0.028
4675,91.396,14,3.445,0.031,0.028
4713,91.795,14.01,3.482,0.031,0.029
4751,92.188,14.01,3.521,0.031,0.029
4789,92.582,14.02,3.559,0.031,0.029
4827,92.968,14.02,3.597,0.031,0.03
4865,93.352,14.02,3.635,0.031,0.03
4903,93.712,14.04,3.671,0.031,0.03
4941,94.09,14.04,3.709,0.031,0.031
4979,94.452,14.05,3.745,0.031,0.031
5017,94.802,14.05,3.781,0.031,0.031
5055,95.168,14.05,3.82,0.031,0.031
5093,95.524,14.06,3.857,0.031,0.032
5131,95.884,14.07,3.895,0.031,0.032
5169,96.244,14.07,3.933,0.031,0.032
5207,96.596,14.07,3.971,0.031,0.033
5245,96.94,14.09,4.008,0.031,0.033
5283,97.288,14.1,4.046,0.031,0.033
5321,97.628,14.12,4.083,0.031,0.034
5359,97.972,14.12,4.121,0.031,0.034
5397,98.296,14.14,4.157,0.031,0.034
5435,98.624,14.15,4.194,0.031,0.035
5473,98.951,14.16,4.23,0.031,0.035
5511,99.291,14.18,4.269,0.032,0.035
5549,99.623,14.19,4.307,0.032,0.035
5587,99.952,14.2,4.345,0.032,0.036
5625,100.264,14.22,4.381,0.032,0.036
5663,100.591,14.23,4.419,0.032,0.036
5701,100.915,14.25,4.457,0.032,0.037
5739,101.227,14.26,4.494,0.032,0.037
5777,101.542,14.27,4.531,0.032,0.037
5815,101.855,14.29,4.569,0.032,0.038
5853,102.164,14.3,4.606,0.032,0.038
5891,102.472,14.31,4.643,0.032,0.038
5929,102.784,14.32,4.681,0.032,0.039
5967,103.082,14.34,4.717,0.032,0.039
6005,103.39,14.35,4.755,0.032,0.039
6043,103.697,14.37,4.793,0.032,0.039
6081,104,14.38,4.831,0.032,0.04
6119,104.288,14.4,4.866,0.032,0.04
6157,104.586,14.42,4.904,0.032,0.04
6195,104.884,14.43,4.942,0.032,0.041
6233,105.168,14.45,4.978,0.032,0.041
6271,105.465,14.47,5.016,0.032,0.041
6309,105.76,14.48,5.054,0.032,0.042
6347,106.056,14.5,5.092,0.032,0.042
6385,106.345,14.51,5.129,0.032,0.042
6423,106.632,14.53,5.167,0.032,0.043
6461,106.919,14.54,5.204,0.032,0.043
6499,107.206,14.55,5.242,0.032,0.043
6537,107.486,14.57,5.279,0.032,0.043
6575,107.76,14.58,5.315,0.032,0.044
6613,108.04,14.6,5.353,0.032,0.044
6651,108.32,14.62,5.39,0.032,0.044
6689,108.6,14.63,5.428,0.033,0.045
6727,108.88,14.65,5.466,0.033,0.045
6765,109.146,14.67,5.502,0.033,0.045
6803,109.431,14.68,5.541,0.033,0.046
6841,109.697,14.69,5.577,0.033,0.046
6879,109.968,14.71,5.615,0.033,0.046
6917,110.25,14.72,5.654,0.033,0.047
6955,110.515,14.74,5.691,0.033,0.047
6993,110.788,14.75,5.729,0.033,0.047
7031,111.051,14.76,5.766,0.033,0.047
7069,111.32,14.77,5.804,0.033,0.048
7107,111.595,14.78,5.843,0.033,0.048
7145,111.868,14.8,5.882,0.033,0.048
7183,112.127,14.82,5.919,0.033,0.049
7221,112.391,14.82,5.957,0.033,0.049
7259,112.656,14.82,5.995,0.033,0.049
7297,112.912,14.83,6.032,0.033,0.05
7335,113.167,14.84,6.069,0.033,0.05
7373,113.42,14.86,6.106,0.033,0.05
7411,113.679,14.87,6.144,0.033,0.051
7449,113.943,14.89,6.183,0.033,0.051
7487,114.194,14.91,6.22,0.033,0.051
7525,114.45,14.93,6.258,0.033,0.052
7563,114.705,14.94,6.296,0.033,0.052
7601,114.956,14.96,6.334,0.033,0.052
7639,115.205,14.98,6.371,0.033,0.052
7677,115.448,14.99,6.408,0.033,0.053
7715,115.701,15,6.446,0.033,0.053
7753,115.951,15.02,6.484,0.033,0.053
7791,116.199,15.03,6.522,0.033,0.054
7829,116.443,15.04,6.559,0.033,0.054
7867,116.683,15.06,6.595,0.033,0.054
7905,116.927,15.07,6.634,0.033,0.055
7943,117.178,15.09,6.672,0.034,0.055
7981,117.43,15.1,6.711,0.034,0.055
8019,117.675,15.11,6.75,0.034,0.056
8057,117.923,15.13,6.789,0.034,0.056
8095,118.167,15.14,6.827,0.034,0.056
8133,118.404,15.16,6.864,0.034,0.056
8171,118.643,15.17,6.902,0.034,0.057
8209,118.882,15.18,6.94,0.034,0.057
8247,119.121,15.19,6.978,0.034,0.057
8285,119.353,15.2,7.015,0.034,0.058
8323,119.588,15.21,7.053,0.034,0.058
8361,119.823,15.23,7.091,0.034,0.058
8399,120.072,15.24,7.131,0.034,0.059
8437,120.306,15.25,7.168,0.034,0.059
8475,120.539,15.26,7.207,0.034,0.059
8513,120.771,15.28,7.245,0.034,0.06
8551,120.999,15.29,7.282,0.034,0.06
8589,121.223,15.3,7.319,0.034,0.06
8627,121.453,15.31,7.357,0.034,0.061
8665,121.687,15.32,7.395,0.034,0.061
8703,121.911,15.34,7.433,0.034,0.061
8741,122.139,15.35,7.471,0.034,0.061
8779,122.367,15.36,7.509,0.034,0.062
8817,122.601,15.37,7.548,0.034,0.062
8855,122.832,15.38,7.587,0.034,0.062
8893,123.051,15.39,7.624,0.034,0.063
8931,123.282,15.4,7.663,0.034,0.063
8969,123.503,15.42,7.701,0.034,0.063
9007,123.733,15.43,7.74,0.034,0.064
9045,123.955,15.43,7.778,0.034,0.064
9083,124.172,15.44,7.815,0.034,0.064
9121,124.403,15.44,7.855,0.034,0.065
9159,124.622,15.45,7.892,0.034,0.065
9197,124.839,15.47,7.93,0.034,0.065
9235,125.062,15.48,7.969,0.034,0.066
9273,125.275,15.5,8.007,0.034,0.066
9311,125.487,15.51,8.044,0.034,0.066
9349,125.701,15.52,8.081,0.034,0.067
9387,125.92,15.53,8.12,0.035,0.067
9425,126.131,15.54,8.157,0.035,0.067
9463,126.351,15.55,8.196,0.035,0.067
9501,126.565,15.57,8.234,0.035,0.068
9539,126.779,15.58,8.272,0.035,0.068
9577,126.991,15.59,8.31,0.035,0.068
9615,127.207,15.6,8.349,0.035,0.069
9653,127.419,15.61,8.387,0.035,0.069
9691,127.624,15.62,8.424,0.035,0.069
9729,127.834,15.63,8.462,0.035,0.07
9767,128.043,15.64,8.5,0.035,0.07
9805,128.255,15.65,8.538,0.035,0.07
9843,128.455,15.66,8.575,0.035,0.071
9881,128.672,15.66,8.614,0.035,0.071
9919,128.883,15.67,8.653,0.035,0.071
9957,129.095,15.67,8.692,0.035,0.072
9995,129.299,15.67,8.73,0.035,0.072
10033,129.509,15.69,8.768,0.035,0.072
10071,129.715,15.7,8.807,0.035,0.072
10109,129.915,15.72,8.844,0.035,0.073
10147,130.129,15.73,8.884,0.035,0.073
10185,130.331,15.75,8.922,0.035,0.073
10223,130.539,15.76,8.961,0.035,0.074
10261,130.742,15.77,8.998,0.035,0.074
10299,130.946,15.78,9.037,0.035,0.074
10337,131.151,15.79,9.076,0.035,0.075
10375,131.356,15.8,9.115,0.035,0.075
10413,131.557,15.8,9.153,0.035,0.075
10451,131.761,15.8,9.192,0.035,0.076
10489,131.965,15.81,9.231,0.035,0.076
10527,132.167,15.83,9.27,0.035,0.076
10565,132.363,15.84,9.308,0.035,0.077
10603,132.559,15.85,9.346,0.035,0.077
10641,132.758,15.85,9.384,0.035,0.077
10679,132.948,15.86,9.421,0.035,0.078
10717,133.142,15.87,9.458,0.035,0.078
10755,133.345,15.88,9.498,0.035,0.078
10793,133.538,15.9,9.536,0.035,0.078
10831,133.743,15.91,9.576,0.035,0.079
10869,133.933,15.92,9.613,0.035,0.079
10907,134.134,15.93,9.653,0.035,0.079
10945,134.331,15.93,9.692,0.035,0.08
10983,134.534,15.94,9.732,0.035,0.08
11021,134.726,15.95,9.769,0.035,0.08
11059,134.926,15.96,9.81,0.035,0.081
11097,135.121,15.97,9.848,0.035,0.081
11135,135.313,15.98,9.887,0.036,0.081
11173,135.506,15.98,9.926,0.036,0.082
11211,135.699,16,9.964,0.036,0.082
11249,135.895,16.01,10.004,0.036,0.082
11287,136.083,16.02,10.042,0.036,0.083
11325,136.276,16.03,10.081,0.036,0.083
11363,136.462,16.04,10.119,0.036,0.083
11401,136.653,16.05,10.157,0.036,0.084
11439,136.842,16.06,10.196,0.036,0.084
11477,137.027,16.07,10.234,0.036,0.084
11515,137.218,16.08,10.273,0.036,0.085
11553,137.405,16.08,10.311,0.036,0.085
11591,137.585,16.09,10.348,0.036,0.085
11629,137.767,16.1,10.386,0.036,0.085
11667,137.944,16.12,10.422,0.036,0.086
11705,138.13,16.13,10.461,0.036,0.086
11743,138.313,16.13,10.499,0.036,0.086
11781,138.502,16.14,10.539,0.036,0.087
11819,138.691,16.14,10.578,0.036,0.087
11857,138.879,16.15,10.617,0.036,0.087
11895,139.061,16.16,10.655,0.036,0.088
11933,139.245,16.17,10.694,0.036,0.088
11971,139.43,16.18,10.732,0.036,0.088
12009,139.603,16.18,10.77,0.036,0.089
12047,139.782,16.19,10.808,0.036,0.089
12085,139.967,16.2,10.847,0.036,0.089
12123,140.162,16.21,10.887,0.036,0.09
12161,140.339,16.22,10.926,0.036,0.09
12199,140.519,16.23,10.964,0.036,0.09
12237,140.698,16.24,11.003,0.036,0.091
12275,140.883,16.24,11.042,0.036,0.091
12313,141.062,16.24,11.081,0.036,0.091
12351,141.238,16.23,11.119,0.036,0.092
12389,141.419,16.22,11.158,0.036,0.092
12427,141.587,16.23,11.194,0.036,0.092
12465,141.766,16.25,11.232,0.036,0.092
12503,141.95,16.26,11.272,0.036,0.093
12541,142.127,16.27,11.312,0.036,0.093
12579,142.305,16.28,11.35,0.036,0.093
12617,142.474,16.29,11.387,0.036,0.094
12655,142.664,16.3,11.429,0.036,0.094
12693,142.835,16.31,11.467,0.036,0.094
12731,143.014,16.31,11.507,0.036,0.095
12769,143.182,16.32,11.544,0.036,0.095
12807,143.359,16.32,11.583,0.036,0.095
12845,143.535,16.33,11.622,0.036,0.096
12883,143.71,16.34,11.661,0.036,0.096
12921,143.889,16.34,11.7,0.036,0.096
12959,144.055,16.35,11.738,0.036,0.097
12997,144.238,16.36,11.779,0.036,0.097
13035,144.414,16.37,11.818,0.036,0.097
13073,144.589,16.38,11.857,0.036,0.098
13111,144.761,16.39,11.896,0.036,0.098
13149,144.934,16.4,11.935,0.036,0.098
13187,145.111,16.4,11.975,0.036,0.099
13225,145.294,16.41,12.017,0.036,0.099
13263,145.466,16.42,12.056,0.036,0.099
13301,145.64,16.43,12.095,0.037,0.1
13339,145.81,16.43,12.134,0.037,0.1
13377,145.978,16.44,12.173,0.037,0.1
13415,146.161,16.44,12.214,0.037,0.101
13453,146.326,16.45,12.252,0.037,0.101
13491,146.497,16.46,12.291,0.037,0.101
13529,146.666,16.46,12.331,0.037,0.101
13567,146.829,16.47,12.368,0.037,0.102
13605,146.998,16.48,12.407,0.037,0.102
13643,147.166,16.48,12.446,0.037,0.102
13681,147.343,16.49,12.487,0.037,0.103
13719,147.498,16.5,12.523,0.037,0.103
13757,147.666,16.51,12.563,0.037,0.103
13795,147.839,16.51,12.603,0.037,0.104
13833,148.002,16.52,12.64,0.037,0.104
13871,148.166,16.53,12.68,0.037,0.104
13909,148.33,16.54,12.717,0.037,0.105
13947,148.494,16.55,12.757,0.037,0.105
13985,148.657,16.56,12.795,0.037,0.105
14023,148.83,16.56,12.836,0.037,0.106
14061,148.997,16.57,12.875,0.037,0.106
14099,149.155,16.58,12.913,0.037,0.106
14137,149.321,16.59,12.952,0.037,0.107
14175,149.489,16.59,12.992,0.037,0.107
14213,149.654,16.6,13.032,0.037,0.107
14251,149.818,16.61,13.071,0.037,0.108
14289,149.98,16.61,13.11,0.037,0.108
14327,150.151,16.61,13.151,0.037,0.108
14365,150.322,16.61,13.192,0.037,0.109
14403,150.485,16.62,13.231,0.037,0.109
14441,150.646,16.63,13.27,0.037,0.109
14479,150.806,16.64,13.309,0.037,0.11
14517,150.973,16.66,13.349,0.037,0.11
14555,151.135,16.67,13.389,0.037,0.11
14593,151.298,16.68,13.428,0.037,0.111
14631,151.46,16.69,13.467,0.037,0.111
14669,151.622,16.69,13.507,0.037,0.111
14707,151.778,16.7,13.546,0.037,0.111
14745,151.934,16.71,13.583,0.037,0.112
14783,152.098,16.71,13.624,0.037,0.112
14821,152.263,16.72,13.664,0.037,0.112
14859,152.414,16.73,13.702,0.037,0.113
14897,152.579,16.74,13.742,0.037,0.113
14935,152.732,16.74,13.78,0.037,0.113
14973,152.894,16.76,13.82,0.037,0.114
15011,153.053,16.76,13.859,0.037,0.114
15049,153.205,16.77,13.897,0.037,0.114
15087,153.358,16.78,13.936,0.037,0.115
15125,153.534,16.79,13.979,0.037,0.115
15163,153.705,16.8,14.021,0.037,0.115
15201,153.858,16.81,14.06,0.037,0.116
15239,154.015,16.82,14.099,0.037,0.116
15277,154.186,16.82,14.143,0.037,0.116
15315,154.345,16.83,14.182,0.037,0.117
15353,154.502,16.84,14.222,0.037,0.117
15391,154.658,16.85,14.26,0.037,0.117
15429,154.82,16.86,14.302,0.037,0.118
15467,154.981,16.87,14.342,0.037,0.118
15505,155.134,16.88,14.382,0.038,0.118
15543,155.29,16.89,14.422,0.038,0.119
15581,155.446,16.9,14.461,0.038,0.119
15619,155.602,16.91,14.501,0.038,0.119
15657,155.762,16.92,14.542,0.038,0.12
15695,155.924,16.93,14.583,0.038,0.12
15733,156.08,16.93,14.623,0.038,0.12
15771,156.231,16.94,14.662,0.038,0.121
15809,156.39,16.95,14.702,0.038,0.121
15847,156.542,16.96,14.742,0.038,0.121
15885,156.704,16.97,14.783,0.038,0.122
15923,156.857,16.98,14.822,0.038,0.122
15961,157.016,16.98,14.864,0.038,0.122
15999,157.177,17,14.905,0.038,0.123
16037,157.33,17.01,14.946,0.038,0.123
16075,157.486,17.02,14.986,0.038,0.123
16113,157.645,17.02,15.027,0.038,0.124
16151,157.804,17.03,15.069,0.038,0.124
16189,157.958,17.04,15.109,0.038,0.124
16227,158.116,17.04,15.15,0.038,0.125
16265,158.266,17.05,15.19,0.038,0.125
16303,158.428,17.06,15.232,0.038,0.125
16341,158.578,17.07,15.272,0.038,0.126
16379,158.734,17.08,15.313,0.038,0.126
16417,158.888,17.09,15.353,0.038,0.126
16455,159.044,17.1,15.394,0.038,0.127
16493,159.2,17.11,15.436,0.038,0.127
16531,159.354,17.12,15.477,0.038,0.127
16569,159.51,17.12,15.518,0.038,0.128
16607,159.666,17.13,15.56,0.038,0.128
16645,159.822,17.14,15.601,0.038,0.128
16683,159.982,17.15,15.644,0.038,0.129
16721,160.152,17.16,15.689,0.038,0.129
16759,160.31,17.17,15.732,0.038,0.129
16797,160.47,17.18,15.775,0.038,0.13
16835,160.626,17.19,15.817,0.038,0.13
16873,160.778,17.2,15.858,0.038,0.131
16911,160.933,17.21,15.898,0.038,0.131
16949,161.09,17.22,15.942,0.038,0.131
16987,161.248,17.23,15.984,0.038,0.132
17025,161.413,17.24,16.029,0.038,0.132
17063,161.566,17.25,16.069,0.038,0.132
17101,161.724,17.25,16.113,0.038,0.133
17139,161.882,17.26,16.156,0.038,0.133
17177,162.038,17.27,16.199,0.038,0.133
17215,162.19,17.28,16.24,0.038,0.134
17253,162.352,17.29,16.284,0.038,0.134
17291,162.506,17.3,16.327,0.038,0.134
17329,162.664,17.31,16.37,0.038,0.135
17367,162.817,17.33,16.412,0.039,0.135
17405,162.976,17.34,16.455,0.039,0.135
17443,163.126,17.34,16.497,0.039,0.136
17481,163.282,17.35,16.54,0.039,0.136
17519,163.438,17.36,16.583,0.039,0.136
17557,163.598,17.37,16.627,0.039,0.137
17595,163.754,17.38,16.671,0.039,0.137
17633,163.907,17.39,16.713,0.039,0.138
17671,164.058,17.39,16.755,0.039,0.138
17709,164.221,17.39,16.801,0.039,0.138
17747,164.38,17.4,16.844,0.039,0.139
17785,164.536,17.41,16.888,0.039,0.139
17823,164.694,17.43,16.933,0.039,0.139
17861,164.853,17.44,16.976,0.039,0.14
17899,165.01,17.45,17.021,0.039,0.14
17937,165.165,17.46,17.065,0.039,0.14
17975,165.328,17.47,17.11,0.039,0.141
18013,165.489,17.48,17.156,0.039,0.141
18051,165.648,17.49,17.2,0.039,0.142
18089,165.8,17.5,17.243,0.039,0.142
18127,165.961,17.5,17.29,0.039,0.142
18165,166.128,17.51,17.336,0.039,0.143
18203,166.277,17.52,17.38,0.039,0.143
18241,166.432,17.53,17.423,0.039,0.143
18279,166.582,17.54,17.466,0.039,0.144
18317,166.734,17.55,17.51,0.039,0.144
18355,166.894,17.55,17.555,0.039,0.144
18393,167.054,17.56,17.6,0.039,0.145
18431,167.214,17.57,17.647,0.039,0.145
18469,167.365,17.58,17.691,0.039,0.146
18507,167.524,17.59,17.736,0.039,0.146
18545,167.673,17.6,17.779,0.039,0.146
18583,167.839,17.61,17.827,0.039,0.147
18621,167.993,17.62,17.872,0.039,0.147
18659,168.157,17.63,17.918,0.039,0.147
18697,168.316,17.63,17.964,0.039,0.148
18735,168.474,17.65,18.01,0.039,0.148
18773,168.634,17.66,18.057,0.039,0.149
18811,168.789,17.67,18.103,0.039,0.149
18849,168.946,17.68,18.148,0.039,0.149
18887,169.099,17.69,18.193,0.039,0.15
18925,169.254,17.7,18.238,0.039,0.15
18963,169.405,17.71,18.283,0.039,0.15
19001,169.562,17.72,18.329,0.039,0.151
19039,169.717,17.73,18.374,0.039,0.151
19077,169.874,17.73,18.42,0.039,0.152
19115,170.04,17.74,18.469,0.039,0.152
19153,170.192,17.75,18.514,0.039,0.152
19191,170.346,17.76,18.56,0.039,0.153
19229,170.506,17.78,18.607,0.04,0.153
19267,170.662,17.79,18.653,0.04,0.154
19305,170.822,17.8,18.701,0.04,0.154
19343,170.977,17.81,18.747,0.04,0.154
19381,171.134,17.82,18.794,0.04,0.155
19419,171.294,17.83,18.841,0.04,0.155
19457,171.45,17.84,18.888,0.04,0.155
19495,171.616,17.85,18.937,0.04,0.156
19533,171.766,17.86,18.982,0.04,0.156
19571,171.921,17.87,19.029,0.04,0.157
19609,172.078,17.88,19.076,0.04,0.157
19647,172.233,17.89,19.123,0.04,0.157
19685,172.39,17.89,19.17,0.04,0.158
19723,172.55,17.91,19.218,0.04,0.158
19761,172.701,17.92,19.264,0.04,0.159
19799,172.862,17.93,19.313,0.04,0.159
19837,173.024,17.94,19.361,0.04,0.159
19875,173.176,17.95,19.407,0.04,0.16
19913,173.334,17.96,19.456,0.04,0.16
19951,173.489,17.97,19.503,0.04,0.161
19989,173.648,17.98,19.551,0.04,0.161
20027,173.803,17.99,19.598,0.04,0.161
20065,173.958,18,19.646,0.04,0.162
20103,174.119,18.01,19.695,0.04,0.162
20141,174.274,18.02,19.743,0.04,0.162
20179,174.44,18.03,19.793,0.04,0.163
20217,174.593,18.04,19.841,0.04,0.163
20255,174.756,18.06,19.89,0.04,0.164
20293,174.913,18.07,19.939,0.04,0.164
20331,175.08,18.08,19.99,0.04,0.165
20369,175.245,18.09,20.041,0.04,0.165
20407,175.402,18.1,20.091,0.04,0.165
20445,175.561,18.11,20.139,0.04,0.166
20483,175.717,18.12,20.188,0.04,0.166
20521,175.88,18.13,20.238,0.04,0.167
20559,176.034,18.14,20.287,0.04,0.167
20597,176.189,18.15,20.336,0.04,0.167
20635,176.351,18.16,20.386,0.04,0.168
20673,176.508,18.17,20.435,0.04,0.168
20711,176.661,18.18,20.483,0.04,0.169
20749,176.82,18.19,20.532,0.04,0.169
20787,176.969,18.2,20.58,0.04,0.169
20825,177.126,18.21,20.629,0.04,0.17
20863,177.285,18.22,20.68,0.04,0.17
20901,177.448,18.24,20.73,0.041,0.171
20939,177.601,18.25,20.779,0.041,0.171
20977,177.761,18.26,20.83,0.041,0.171
21015,177.92,18.27,20.879,0.041,0.172
21053,178.073,18.28,20.929,0.041,0.172
21091,178.23,18.3,20.978,0.041,0.173
21129,178.388,18.31,21.028,0.041,0.173
21167,178.543,18.32,21.078,0.041,0.173
21205,178.694,18.33,21.126,0.041,0.174
21243,178.85,18.34,21.176,0.041,0.174
21281,179.001,18.35,21.224,0.041,0.175
21319,179.16,18.36,21.274,0.041,0.175
21357,179.315,18.37,21.324,0.041,0.176
21395,179.469,18.38,21.375,0.041,0.176
21433,179.625,18.37,21.425,0.041,0.176
21471,179.784,18.38,21.475,0.041,0.177
21509,179.933,18.39,21.524,0.041,0.177
21547,180.102,18.39,21.578,0.041,0.178
21585,180.261,18.4,21.63,0.041,0.178
21623,180.422,18.41,21.682,0.041,0.178
21661,180.577,18.42,21.732,0.041,0.179
21699,180.733,18.42,21.783,0.041,0.179
21737,180.889,18.43,21.834,0.041,0.18
21775,181.041,18.44,21.884,0.041,0.18
21813,181.201,18.45,21.936,0.041,0.181
21851,181.359,18.46,21.987,0.041,0.181
21889,181.526,18.47,22.042,0.041,0.181
21927,181.681,18.47,22.093,0.041,0.182
21965,181.837,18.48,22.144,0.041,0.182
22003,181.997,18.49,22.197,0.041,0.183
22041,182.153,18.49,22.248,0.041,0.183
22079,182.313,18.5,22.301,0.041,0.184
22117,182.472,18.51,22.352,0.041,0.184
22155,182.628,18.52,22.404,0.041,0.184
22193,182.783,18.53,22.456,0.041,0.185
22231,182.94,18.54,22.507,0.041,0.185
22269,183.089,18.55,22.558,0.041,0.186
22307,183.245,18.55,22.608,0.041,0.186
22345,183.395,18.56,22.659,0.041,0.186
22383,183.556,18.57,22.712,0.041,0.187
22421,183.713,18.58,22.766,0.041,0.187
22459,183.874,18.58,22.819,0.041,0.188
22497,184.029,18.6,22.871,0.041,0.188
22535,184.186,18.61,22.924,0.041,0.189
22573,184.347,18.61,22.977,0.041,0.189
22611,184.503,18.62,23.03,0.041,0.19
22649,184.657,18.63,23.082,0.041,0.19
22687,184.813,18.63,23.135,0.041,0.19
22725,184.975,18.64,23.189,0.041,0.191
22763,185.13,18.65,23.242,0.041,0.191
22801,185.289,18.66,23.296,0.041,0.192
22839,185.443,18.67,23.348,0.041,0.192
22877,185.597,18.68,23.401,0.042,0.193
22915,185.753,18.69,23.454,0.042,0.193
22953,185.914,18.7,23.508,0.042,0.193
22991,186.067,18.71,23.56,0.042,0.194
23029,186.226,18.71,23.614,0.042,0.194
23067,186.385,18.72,23.668,0.042,0.195
23105,186.545,18.73,23.724,0.042,0.195
23143,186.706,18.74,23.779,0.042,0.196
23181,186.863,18.75,23.832,0.042,0.196
23219,187.023,18.76,23.887,0.042,0.197
23257,187.177,18.77,23.941,0.042,0.197
23295,187.329,18.78,23.994,0.042,0.197
23333,187.494,18.79,24.05,0.042,0.198
23371,187.645,18.8,24.103,0.042,0.198
23409,187.81,18.8,24.16,0.042,0.199
23447,187.961,18.81,24.212,0.042,0.199
23485,188.121,18.82,24.268,0.042,0.2
23523,188.273,18.83,24.321,0.042,0.2
23561,188.433,18.84,24.376,0.042,0.201
23599,188.591,18.86,24.431,0.042,0.201
23637,188.746,18.87,24.485,0.042,0.202
23675,188.901,18.88,24.54,0.042,0.202
23713,189.061,18.88,24.596,0.042,0.202
23751,189.224,18.89,24.652,0.042,0.203
23789,189.381,18.9,24.706,0.042,0.203
23827,189.535,18.91,24.761,0.042,0.204
23865,189.691,18.92,24.816,0.042,0.204
23903,189.845,18.93,24.871,0.042,0.205
23941,190.003,18.94,24.926,0.042,0.205
23979,190.169,18.95,24.985,0.042,0.206
24017,190.341,18.96,25.046,0.042,0.206
24055,190.491,18.97,25.099,0.042,0.207
24093,190.653,18.97,25.157,0.042,0.207
24131,190.816,18.96,25.214,0.042,0.208
24169,190.975,18.97,25.271,0.042,0.208
24207,191.129,18.98,25.326,0.042,0.208
24245,191.285,18.99,25.382,0.042,0.209
24283,191.441,18.99,25.438,0.042,0.209
24321,191.601,19,25.495,0.042,0.21
24359,191.757,19.01,25.551,0.042,0.21
24397,191.915,19.02,25.607,0.042,0.211
24435,192.076,19.03,25.664,0.042,0.211
24473,192.233,19.04,25.722,0.042,0.212
24511,192.393,19.05,25.779,0.042,0.212
24549,192.545,19.06,25.834,0.042,0.213
24587,192.7,19.07,25.89,0.042,0.213
24625,192.853,19.08,25.945,0.042,0.214
24663,193.025,19.09,26.008,0.042,0.214
24701,193.188,19.09,26.066,0.042,0.215
24739,193.341,19.1,26.122,0.042,0.215
24777,193.495,19.11,26.178,0.042,0.215
24815,193.647,19.12,26.233,0.042,0.216
24853,193.809,19.13,26.293,0.043,0.216
24891,193.965,19.14,26.35,0.043,0.217
24929,194.121,19.15,26.407,0.043,0.217
24967,194.273,19.16,26.462,0.043,0.218
25005,194.429,19.17,26.519,0.043,0.218
25043,194.589,19.18,26.578,0.043,0.219
25081,194.743,19.18,26.634,0.043,0.219
25119,194.899,19.19,26.691,0.043,0.22
25157,195.049,19.19,26.747,0.043,0.22
25195,195.207,19.2,26.805,0.043,0.221
25233,195.358,19.21,26.861,0.043,0.221
25271,195.517,19.22,26.92,0.043,0.222
25309,195.673,19.23,26.978,0.043,0.222
25347,195.829,19.24,27.036,0.043,0.223
25385,195.989,19.25,27.095,0.043,0.223
25423,196.144,19.25,27.153,0.043,0.223
25461,196.307,19.26,27.213,0.043,0.224
25499,196.463,19.27,27.271,0.043,0.224
25537,196.615,19.28,27.328,0.043,0.225
25575,196.773,19.29,27.387,0.043,0.225
25613,196.929,19.3,27.446,0.043,0.226
25651,197.088,19.31,27.506,0.043,0.226
25689,197.249,19.32,27.566,0.043,0.227
25727,197.409,19.32,27.624,0.043,0.227
25765,197.56,19.33,27.683,0.043,0.228
25803,197.717,19.34,27.742,0.043,0.228
25841,197.875,19.35,27.801,0.043,0.229
25879,198.029,19.36,27.86,0.043,0.229
25917,198.187,19.37,27.919,0.043,0.23
25955,198.339,19.38,27.976,0.043,0.23
25993,198.502,19.39,28.038,0.043,0.231
26031,198.661,19.39,28.097,0.043,0.231
26069,198.813,19.4,28.157,0.043,0.232
26107,198.968,19.41,28.215,0.043,0.232
26145,199.129,19.42,28.277,0.043,0.233
26183,199.28,19.42,28.335,0.043,0.233
26221,199.437,19.44,28.395,0.043,0.234
26259,199.597,19.45,28.456,0.043,0.234
26297,199.753,19.46,28.516,0.043,0.235
26335,199.91,19.47,28.575,0.043,0.235
26373,200.073,19.47,28.638,0.043,0.236
26411,200.229,19.48,28.698,0.043,0.236
26449,200.385,19.49,28.758,0.043,0.237
26487,200.543,19.49,28.819,0.043,0.237
26525,200.696,19.51,28.879,0.043,0.238
26563,200.853,19.52,28.938,0.043,0.238
26601,201.008,19.53,28.999,0.043,0.239
26639,201.164,19.54,29.06,0.043,0.239
26677,201.317,19.54,29.119,0.043,0.24
26715,201.483,19.55,29.182,0.043,0.24
26753,201.638,19.56,29.243,0.043,0.241
26791,201.799,19.57,29.305,0.043,0.241
26829,201.948,19.58,29.365,0.044,0.242
26867,202.113,19.59,29.429,0.044,0.242
26905,202.273,19.6,29.491,0.044,0.243
26943,202.428,19.61,29.552,0.044,0.243
26981,202.581,19.61,29.612,0.044,0.244
27019,202.746,19.62,29.676,0.044,0.244
27057,202.903,19.63,29.737,0.044,0.245
27095,203.059,19.64,29.799,0.044,0.245
27133,203.213,19.65,29.859,0.044,0.246
27171,203.371,19.66,29.922,0.044,0.246
27209,203.524,19.67,29.983,0.044,0.247
27247,203.695,19.68,30.05,0.044,0.247
27285,203.851,19.68,30.111,0.044,0.248
27323,204.003,19.69,30.172,0.044,0.248
27361,204.153,19.7,30.232,0.044,0.249
27399,204.305,19.71,30.292,0.044,0.249
27437,204.457,19.72,30.353,0.044,0.25
27475,204.613,19.73,30.415,0.044,0.25
27513,204.771,19.74,30.477,0.044,0.251
27551,204.931,19.75,30.541,0.044,0.251
27589,205.09,19.75,30.605,0.044,0.252
27627,205.245,19.76,30.667,0.044,0.252
27665,205.403,19.77,30.73,0.044,0.253
27703,205.558,19.78,30.793,0.044,0.253
27741,205.709,19.79,30.854,0.044,0.254
27779,205.86,19.8,30.915,0.044,0.254
27817,206.017,19.81,30.976,0.044,0.255
27855,206.169,19.81,31.039,0.044,0.255
27893,206.324,19.82,31.102,0.044,0.256
27931,206.479,19.83,31.163,0.044,0.256
27969,206.632,19.83,31.225,0.044,0.257
28007,206.789,19.84,31.29,0.044,0.258
28045,206.945,19.85,31.353,0.044,0.258
28083,207.102,19.86,31.416,0.044,0.259
28121,207.26,19.88,31.481,0.044,0.259
28159,207.417,19.88,31.545,0.044,0.26
28197,207.575,19.89,31.608,0.044,0.26
28235,207.724,19.9,31.67,0.044,0.261
28273,207.881,19.91,31.734,0.044,0.261
28311,208.044,19.91,31.801,0.044,0.262
28349,208.198,19.92,31.864,0.044,0.262
28387,208.354,19.93,31.928,0.044,0.263
28425,208.509,19.95,31.992,0.044,0.263
28463,208.672,19.95,32.059,0.044,0.264
28501,208.829,19.96,32.123,0.044,0.264
28539,208.988,19.97,32.189,0.044,0.265
28577,209.148,19.98,32.255,0.044,0.265
28615,209.309,19.98,32.321,0.044,0.266
28653,209.464,20,32.386,0.044,0.267
28691,209.623,20.01,32.451,0.044,0.267
28729,209.776,20.02,32.515,0.044,0.268
28767,209.932,20.02,32.58,0.044,0.268
28805,210.095,20.03,32.647,0.045,0.269
28843,210.243,20.04,32.708,0.045,0.269
28881,210.4,20.04,32.775,0.045,0.27
28919,210.557,20.05,32.84,0.045,0.27
28957,210.712,20.06,32.905,0.045,0.271
28995,210.864,20.07,32.969,0.045,0.271
29033,211.02,20.08,33.034,0.045,0.272
29071,211.176,20.09,33.1,0.045,0.272
29109,211.337,20.09,33.167,0.045,0.273
29147,211.502,20.1,33.236,0.045,0.274
29185,211.657,20.11,33.301,0.045,0.274
29223,211.808,20.12,33.365,0.045,0.275
29261,211.965,20.13,33.431,0.045,0.275
29299,212.125,20.14,33.499,0.045,0.276
29337,212.278,20.15,33.563,0.045,0.276
29375,212.437,20.15,33.631,0.045,0.277
29413,212.6,20.16,33.7,0.045,0.277
29451,212.758,20.17,33.766,0.045,0.278
29489,212.914,20.18,33.833,0.045,0.278
29527,213.068,20.19,33.899,0.045,0.279
29565,213.229,20.2,33.967,0.045,0.28
29603,213.402,20.21,34.041,0.045,0.28
29641,213.559,20.21,34.107,0.045,0.281
29679,213.708,20.22,34.172,0.045,0.281
29717,213.871,20.23,34.241,0.045,0.282
29755,214.029,20.23,34.309,0.045,0.282
29793,214.186,20.24,34.376,0.045,0.283
29831,214.337,20.25,34.442,0.045,0.283
29869,214.496,20.26,34.51,0.045,0.284
29907,214.651,20.27,34.576,0.045,0.285
29945,214.8,20.27,34.641,0.045,0.285
29983,214.962,20.28,34.71,0.045,0.286
30021,215.117,20.29,34.778,0.045,0.286
30059,215.272,20.3,34.845,0.045,0.287
30097,215.428,20.31,34.913,0.045,0.287
30135,215.582,20.32,34.979,0.045,0.288
30173,215.736,20.32,35.047,0.045,0.288
30211,215.888,20.33,35.113,0.045,0.289
30249,216.047,20.33,35.181,0.045,0.29
30287,216.196,20.34,35.247,0.045,0.29
30325,216.352,20.35,35.315,0.045,0.291
30363,216.508,20.36,35.383,0.045,0.291
30401,216.666,20.37,35.451,0.045,0.292
30439,216.816,20.38,35.516,0.045,0.292
30477,216.968,20.39,35.585,0.045,0.293
30515,217.124,20.39,35.653,0.045,0.293
30553,217.288,20.4,35.725,0.045,0.294
30591,217.448,20.41,35.795,0.045,0.295
30629,217.604,20.42,35.864,0.045,0.295
30667,217.76,20.43,35.933,0.045,0.296
30705,217.912,20.44,36,0.045,0.296
30743,218.088,20.45,36.078,0.045,0.297
30781,218.25,20.45,36.149,0.045,0.298
30819,218.405,20.46,36.218,0.045,0.298
30857,218.556,20.46,36.285,0.045,0.299
30895,218.72,20.47,36.358,0.045,0.299
30933,218.878,20.48,36.428,0.046,0.3
30971,219.032,20.49,36.497,0.046,0.3
31009,219.192,20.5,36.568,0.046,0.301
31047,219.352,20.51,36.64,0.046,0.302
31085,219.512,20.51,36.711,0.046,0.302
31123,219.673,20.52,36.783,0.046,0.303
31161,219.828,20.53,36.853,0.046,0.303
31199,219.984,20.54,36.923,0.046,0.304
31237,220.15,20.55,36.996,0.046,0.304
31275,220.304,20.56,37.066,0.046,0.305
31313,220.456,20.57,37.135,0.046,0.306
31351,220.612,20.57,37.205,0.046,0.306
31389,220.769,20.58,37.275,0.046,0.307
31427,220.925,20.59,37.346,0.046,0.307
31465,221.08,20.6,37.416,0.046,0.308
31503,221.243,20.61,37.489,0.046,0.309
31541,221.396,20.62,37.559,0.046,0.309
31579,221.548,20.62,37.628,0.046,0.31
31617,221.704,20.63,37.699,0.046,0.31
31655,221.86,20.64,37.77,0.046,0.311
31693,222.018,20.64,37.841,0.046,0.311
31731,222.172,20.65,37.912,0.046,0.312
31769,222.328,20.66,37.983,0.046,0.313
31807,222.49,20.67,38.056,0.046,0.313
31845,222.646,20.68,38.128,0.046,0.314
31883,222.8,20.68,38.199,0.046,0.314
31921,222.962,20.69,38.273,0.046,0.315
31959,223.123,20.7,38.346,0.046,0.316
31997,223.272,20.71,38.416,0.046,0.316
32035,223.431,20.72,38.488,0.046,0.317
32073,223.582,20.73,38.558,0.046,0.317
32111,223.744,20.73,38.633,0.046,0.318
32149,223.911,20.74,38.709,0.046,0.319
32187,224.068,20.75,38.783,0.046,0.319
32225,224.223,20.76,38.853,0.046,0.32
32263,224.372,20.76,38.924,0.046,0.32
32301,224.527,20.77,38.996,0.046,0.321
32339,224.689,20.78,39.07,0.046,0.322
32377,224.848,20.79,39.145,0.046,0.322
32415,225.009,20.79,39.219,0.046,0.323
32453,225.17,20.8,39.294,0.046,0.323
32491,225.327,20.81,39.366,0.046,0.324
32529,225.482,20.82,39.439,0.046,0.325
32567,225.632,20.83,39.51,0.046,0.325
32605,225.792,20.84,39.585,0.046,0.326
32643,225.947,20.84,39.656,0.046,0.326
32681,226.1,20.84,39.73,0.046,0.327
32719,226.262,20.85,39.805,0.046,0.328
32757,226.42,20.86,39.88,0.046,0.328
32795,226.58,20.87,39.955,0.046,0.329
32833,226.742,20.88,40.031,0.046,0.329
32871,226.9,20.89,40.106,0.046,0.33
32909,227.062,20.89,40.182,0.046,0.331
32947,227.216,20.9,40.256,0.046,0.331
32985,227.372,20.9,40.33,0.046,0.332
33023,227.529,20.91,40.403,0.046,0.333
33061,227.686,20.92,40.477,0.046,0.333
33099,227.836,20.93,40.55,0.047,0.334
33137,227.99,20.94,40.622,0.047,0.334
33175,228.144,20.94,40.696,0.047,0.335
33213,228.3,20.95,40.771,0.047,0.336
33251,228.46,20.96,40.847,0.047,0.336
33289,228.612,20.96,40.92,0.047,0.337
33327,228.768,20.97,40.994,0.047,0.337
33365,228.923,20.98,41.067,0.047,0.338
33403,229.077,20.99,41.142,0.047,0.339
33441,229.232,20.99,41.217,0.047,0.339
33479,229.392,21,41.294,0.047,0.34
33517,229.55,21.01,41.369,0.047,0.34
33555,229.706,21.02,41.444,0.047,0.341
33593,229.856,21.03,41.517,0.047,0.342
33631,230.02,21.03,41.596,0.047,0.342
33669,230.176,21.03,41.672,0.047,0.343
33707,230.334,21.04,41.747,0.047,0.344
33745,230.49,21.05,41.823,0.047,0.344
33783,230.646,21.05,41.898,0.047,0.345
33821,230.803,21.06,41.976,0.047,0.345
33859,230.964,21.07,42.054,0.047,0.346
33897,231.12,21.07,42.13,0.047,0.347
33935,231.275,21.08,42.206,0.047,0.347
33973,231.432,21.09,42.282,0.047,0.348
34011,231.587,21.09,42.358,0.047,0.349
34049,231.744,21.1,42.434,0.047,0.349
34087,231.896,21.11,42.509,0.047,0.35
34125,232.056,21.12,42.587,0.047,0.351
34163,232.207,21.12,42.661,0.047,0.351
34201,232.366,21.13,42.738,0.047,0.352
34239,232.515,21.13,42.813,0.047,0.352
34277,232.668,21.14,42.886,0.047,0.353
34315,232.828,21.15,42.966,0.047,0.354
34353,232.988,21.16,43.045,0.047,0.354
34391,233.144,21.16,43.122,0.047,0.355
34429,233.303,21.16,43.201,0.047,0.356
34467,233.458,21.17,43.277,0.047,0.356
34505,233.61,21.18,43.352,0.047,0.357
34543,233.768,21.18,43.431,0.047,0.357
34581,233.928,21.19,43.511,0.047,0.358
34619,234.082,21.2,43.586,0.047,0.359
34657,234.236,21.2,43.664,0.047,0.359
34695,234.398,21.21,43.744,0.047,0.36
34733,234.548,21.22,43.818,0.047,0.361
34771,234.704,21.22,43.897,0.047,0.361
34809,234.863,21.23,43.977,0.047,0.362
34847,235.028,21.24,44.06,0.047,0.363
34885,235.183,21.24,44.136,0.047,0.363
34923,235.335,21.25,44.214,0.047,0.364
34961,235.492,21.25,44.292,0.047,0.365
34999,235.647,21.26,44.371,0.047,0.365
35037,235.804,21.27,44.449,0.047,0.366
35075,235.966,21.28,44.53,0.047,0.367
35113,236.122,21.28,44.609,0.047,0.367
35151,236.28,21.28,44.689,0.047,0.368
35189,236.44,21.29,44.77,0.047,0.368
35227,236.599,21.29,44.849,0.047,0.369
35265,236.752,21.3,44.928,0.047,0.37
35303,236.91,21.31,45.007,0.047,0.37
35341,237.068,21.32,45.089,0.047,0.371
35379,237.22,21.32,45.166,0.047,0.372
35417,237.385,21.32,45.249,0.047,0.372
35455,237.544,21.33,45.331,0.047,0.373
35493,237.706,21.33,45.413,0.047,0.374
35531,237.86,21.34,45.492,0.047,0.374
35569,238.019,21.35,45.574,0.047,0.375
35607,238.176,21.35,45.654,0.047,0.376
35645,238.331,21.36,45.734,0.047,0.376
35683,238.488,21.36,45.814,0.047,0.377
35721,238.644,21.37,45.894,0.047,0.378
35759,238.799,21.38,45.974,0.048,0.378
35797,238.963,21.38,46.059,0.048,0.379
35835,239.12,21.39,46.139,0.048,0.38
35873,239.283,21.39,46.224,0.048,0.38
35911,239.444,21.4,46.306,0.048,0.381
35949,239.596,21.4,46.385,0.048,0.382
35987,239.762,21.41,46.47,0.048,0.382
36025,239.924,21.42,46.555,0.048,0.383
36063,240.095,21.42,46.644,0.048,0.384
36101,240.252,21.42,46.725,0.048,0.385
36139,240.407,21.43,46.804,0.048,0.385
36177,240.563,21.43,46.888,0.048,0.386
36215,240.72,21.44,46.969,0.048,0.387
36253,240.883,21.45,47.055,0.048,0.387
36291,241.039,21.44,47.136,0.048,0.388
36329,241.206,21.44,47.222,0.048,0.389
36367,241.36,21.45,47.304,0.048,0.389
36405,241.516,21.45,47.385,0.048,0.39
36443,241.674,21.46,47.467,0.048,0.391
36481,241.823,21.47,47.547,0.048,0.391
36519,241.976,21.47,47.627,0.048,0.392
36557,242.129,21.47,47.707,0.048,0.393
36595,242.286,21.48,47.789,0.048,0.393
36633,242.442,21.48,47.872,0.048,0.394
36671,242.595,21.49,47.954,0.048,0.395
36709,242.759,21.5,48.041,0.048,0.395
36747,242.915,21.5,48.124,0.048,0.396
36785,243.071,21.5,48.204,0.048,0.397
36823,243.23,21.5,48.289,0.048,0.397
36861,243.379,21.51,48.37,0.048,0.398
36899,243.542,21.51,48.455,0.048,0.399
36937,243.695,21.52,48.538,0.048,0.399
36975,243.857,21.53,48.623,0.048,0.4
37013,244.016,21.53,48.709,0.048,0.401
37051,244.168,21.53,48.79,0.048,0.402
37089,244.32,21.53,48.871,0.048,0.402
37127,244.471,21.54,48.951,0.048,0.403
37165,244.624,21.55,49.034,0.048,0.404
37203,244.779,21.55,49.118,0.048,0.404
37241,244.936,21.55,49.202,0.048,0.405
37279,245.093,21.55,49.286,0.048,0.406
37317,245.248,21.56,49.37,0.048,0.406
37355,245.403,21.56,49.454,0.048,0.407
37393,245.566,21.57,49.54,0.048,0.408
37431,245.723,21.57,49.624,0.048,0.408
37469,245.876,21.58,49.709,0.048,0.409
37507,246.037,21.58,49.795,0.048,0.41
37545,246.195,21.58,49.882,0.048,0.411
37583,246.353,21.59,49.967,0.048,0.411
37621,246.515,21.6,50.056,0.048,0.412
37659,246.676,21.6,50.143,0.048,0.413
37697,246.829,21.6,50.226,0.048,0.413
37735,246.987,21.6,50.313,0.048,0.414
37773,247.139,21.61,50.396,0.048,0.415
37811,247.299,21.61,50.483,0.048,0.415
37849,247.464,21.62,50.573,0.048,0.416
37887,247.623,21.62,50.66,0.048,0.417
37925,247.78,21.62,50.746,0.048,0.418
37963,247.936,21.63,50.832,0.048,0.418
38001,248.099,21.63,50.922,0.048,0.419
38039,248.251,21.64,51.005,0.048,0.42
38077,248.403,21.64,51.089,0.048,0.42
38115,248.564,21.64,51.177,0.048,0.421
38153,248.722,21.65,51.263,0.048,0.422
38191,248.878,21.65,51.349,0.048,0.423
38229,249.035,21.66,51.436,0.048,0.423
38267,249.195,21.66,51.526,0.048,0.424
38305,249.351,21.67,51.613,0.048,0.425
38343,249.511,21.67,51.702,0.048,0.426
38381,249.663,21.67,51.786,0.048,0.426
38419,249.819,21.67,51.873,0.048,0.427
38457,249.975,21.68,51.96,0.048,0.428
38495,250.159,21.69,52.062,0.048,0.428
38533,250.311,21.69,52.147,0.048,0.429
38571,250.471,21.69,52.236,0.048,0.43
38609,250.634,21.69,52.326,0.048,0.431
38647,250.79,21.7,52.413,0.048,0.431
38685,250.943,21.7,52.501,0.048,0.432
38723,251.106,21.71,52.59,0.048,0.433
38761,251.265,21.71,52.68,0.048,0.434
38799,251.423,21.71,52.77,0.048,0.434
38837,251.587,21.71,52.862,0.048,0.435
38875,251.743,21.72,52.95,0.048,0.436
38913,251.903,21.73,53.038,0.048,0.437
38951,252.059,21.73,53.129,0.048,0.437
38989,252.227,21.73,53.221,0.048,0.438
39027,252.381,21.73,53.31,0.048,0.439
39065,252.537,21.73,53.398,0.048,0.439
39103,252.698,21.74,53.489,0.048,0.44
39141,252.851,21.75,53.577,0.048,0.441
39179,253.011,21.75,53.668,0.048,0.442
39217,253.171,21.75,53.759,0.048,0.442
39255,253.323,21.75,53.846,0.048,0.443
39293,253.479,21.76,53.935,0.048,0.444
39331,253.645,21.76,54.029,0.048,0.445
39369,253.801,21.76,54.118,0.048,0.445
39407,253.955,21.77,54.207,0.048,0.446
39445,254.115,21.77,54.299,0.048,0.447
39483,254.271,21.77,54.388,0.048,0.448
39521,254.427,21.78,54.478,0.048,0.448
39559,254.585,21.79,54.567,0.048,0.449
39597,254.741,21.78,54.657,0.048,0.45
39635,254.895,21.79,54.747,0.048,0.451
39673,255.057,21.79,54.839,0.048,0.451
39711,255.213,21.8,54.929,0.048,0.452
39749,255.369,21.8,55.019,0.048,0.453
39787,255.527,21.8,55.112,0.048,0.454
39825,255.682,21.8,55.2,0.048,0.454
39863,255.843,21.81,55.295,0.048,0.455
39901,255.997,21.81,55.383,0.048,0.456
39939,256.155,21.82,55.476,0.048,0.457
39977,256.311,21.82,55.567,0.048,0.457
40015,256.471,21.82,55.657,0.048,0.458
40053,256.626,21.82,55.748,0.048,0.459
40091,256.781,21.83,55.839,0.049,0.46
40129,256.939,21.83,55.933,0.049,0.46
40167,257.111,21.84,56.033,0.049,0.461
40205,257.271,21.84,56.127,0.049,0.462
40243,257.423,21.84,56.216,0.049,0.463
40281,257.583,21.85,56.31,0.049,0.463
40319,257.745,21.85,56.404,0.049,0.464
40357,257.906,21.86,56.498,0.049,0.465
40395,258.063,21.86,56.592,0.049,0.466
40433,258.217,21.86,56.682,0.049,0.467
40471,258.375,21.86,56.776,0.049,0.467
40509,258.535,21.87,56.87,0.049,0.468
40547,258.693,21.87,56.963,0.049,0.469
40585,258.851,21.88,57.055,0.049,0.47
40623,259.007,21.89,57.15,0.049,0.47
40661,259.168,21.89,57.244,0.049,0.471
40699,259.326,21.89,57.339,0.049,0.472
40737,259.485,21.89,57.432,0.049,0.473
40775,259.632,21.9,57.52,0.049,0.473
40813,259.791,21.91,57.615,0.049,0.474
40851,259.947,21.91,57.708,0.049,0.475
40889,260.119,21.91,57.811,0.049,0.476
40927,260.277,21.91,57.904,0.049,0.477
40965,260.43,21.92,57.997,0.049,0.477
41003,260.597,21.92,58.095,0.049,0.478
41041,260.751,21.92,58.189,0.049,0.479
41079,260.907,21.93,58.282,0.049,0.48
41117,261.065,21.93,58.376,0.049,0.48
41155,261.218,21.93,58.467,0.049,0.481
41193,261.373,21.94,58.561,0.049,0.482
41231,261.528,21.94,58.655,0.049,0.483
41269,261.683,21.94,58.749,0.049,0.484
41307,261.838,21.94,58.843,0.049,0.484
41345,261.999,21.94,58.94,0.049,0.485
41383,262.158,21.95,59.034,0.049,0.486
41421,262.321,21.95,59.134,0.049,0.487
41459,262.477,21.95,59.228,0.049,0.487
41497,262.634,21.95,59.323,0.049,0.488
41535,262.787,21.95,59.418,0.049,0.489
41573,262.945,21.96,59.513,0.049,0.49
41611,263.098,21.96,59.605,0.049,0.491
41649,263.258,21.96,59.703,0.049,0.491
41687,263.419,21.96,59.803,0.049,0.492
41725,263.575,21.96,59.898,0.049,0.493
41763,263.734,21.97,59.993,0.049,0.494
41801,263.911,21.97,60.103,0.049,0.495
41839,264.067,21.97,60.199,0.049,0.495
41877,264.226,21.97,60.297,0.049,0.496
41915,264.387,21.97,60.395,0.049,0.497
41953,264.539,21.98,60.486,0.049,0.498
41991,264.694,21.98,60.585,0.049,0.499
42029,264.853,21.98,60.681,0.049,0.499
42067,265.013,21.98,60.779,0.049,0.5
42105,265.163,21.98,60.871,0.049,0.501
42143,265.323,21.98,60.972,0.049,0.502
42181,265.474,21.98,61.066,0.049,0.503
42219,265.631,21.98,61.163,0.049,0.503
42257,265.793,21.98,61.262,0.049,0.504
42295,265.945,21.98,61.356,0.049,0.505
42333,266.105,21.98,61.456,0.049,0.506
42371,266.258,21.98,61.553,0.049,0.507
42409,266.413,21.98,61.647,0.049,0.507
42447,266.566,21.98,61.744,0.049,0.508
42485,266.723,21.98,61.842,0.049,0.509
42523,266.879,21.98,61.939,0.049,0.51
42561,267.05,21.98,62.047,0.049,0.511
42599,267.203,21.98,62.142,0.049,0.511
42637,267.358,21.98,62.24,0.049,0.512
42675,267.517,21.98,62.338,0.049,0.513
42713,267.666,21.98,62.433,0.049,0.514
42751,267.823,21.99,62.531,0.049,0.515
42789,267.983,21.98,62.632,0.049,0.515
42827,268.145,21.98,62.732,0.049,0.516
42865,268.298,21.98,62.831,0.049,0.517
42903,268.455,21.99,62.929,0.049,0.518
42941,268.619,21.99,63.033,0.049,0.519
42979,268.774,21.98,63.132,0.049,0.52
43017,268.931,21.98,63.23,0.049,0.52
43055,269.084,21.98,63.327,0.049,0.521
43093,269.246,21.98,63.428,0.049,0.522
43131,269.402,21.98,63.53,0.049,0.523
43169,269.562,21.98,63.629,0.049,0.524
43207,269.72,21.98,63.731,0.049,0.525
43245,269.876,21.98,63.83,0.049,0.525
43283,270.043,21.98,63.938,0.049,0.526
43321,270.216,21.98,64.048,0.049,0.527
43359,270.374,21.97,64.15,0.049,0.528
43397,270.527,21.97,64.247,0.049,0.529
43435,270.691,21.97,64.352,0.049,0.53
43473,270.846,21.97,64.452,0.049,0.53
43511,271.005,21.97,64.553,0.049,0.531
43549,271.159,21.97,64.653,0.049,0.532
43587,271.316,21.97,64.753,0.049,0.533
43625,271.476,21.97,64.856,0.049,0.534
43663,271.637,21.97,64.96,0.049,0.535
43701,271.798,21.97,65.066,0.049,0.536
43739,271.954,21.96,65.166,0.049,0.536
43777,272.111,21.96,65.267,0.049,0.537
43815,272.266,21.96,65.368,0.049,0.538
43853,272.423,21.96,65.47,0.049,0.539
43891,272.582,21.96,65.573,0.049,0.54
43929,272.743,21.96,65.677,0.049,0.541
43967,272.903,21.96,65.782,0.049,0.541
44005,273.056,21.96,65.881,0.049,0.542
44043,273.213,21.96,65.982,0.049,0.543
44081,273.373,21.95,66.087,0.049,0.544
44119,273.523,21.95,66.186,0.049,0.545
44157,273.678,21.95,66.288,0.049,0.546
44195,273.84,21.95,66.393,0.049,0.546
44233,273.994,21.95,66.495,0.049,0.547
44271,274.151,21.95,66.598,0.049,0.548
44309,274.31,21.94,66.703,0.049,0.549
44347,274.466,21.94,66.805,0.049,0.55
44385,274.626,21.94,66.911,0.049,0.551
44423,274.78,21.94,67.011,0.049,0.552
44461,274.939,21.93,67.116,0.049,0.552
44499,275.094,21.93,67.219,0.049,0.553
44537,275.251,21.93,67.322,0.049,0.554
44575,275.41,21.93,67.428,0.049,0.555
44613,275.573,21.93,67.534,0.049,0.556
44651,275.726,21.92,67.638,0.049,0.557
44689,275.888,21.92,67.744,0.049,0.558
44727,276.038,21.92,67.845,0.049,0.558
44765,276.19,21.92,67.946,0.049,0.559
44803,276.364,21.92,68.061,0.049,0.56
44841,276.519,21.91,68.165,0.049,0.561
44879,276.676,21.91,68.269,0.049,0.562
44917,276.828,21.91,68.37,0.049,0.563
44955,276.982,21.91,68.475,0.049,0.564
44993,277.138,21.9,68.579,0.049,0.564
45031,277.294,21.9,68.684,0.049,0.565
45069,277.446,21.9,68.786,0.049,0.566
45107,277.606,21.9,68.893,0.049,0.567
45145,277.76,21.9,68.996,0.049,0.568
45183,277.923,21.89,69.106,0.049,0.569
45221,278.078,21.88,69.211,0.049,0.57
45259,278.237,21.87,69.316,0.049,0.571
45297,278.389,21.86,69.419,0.049,0.571
45335,278.548,21.87,69.527,0.049,0.572
45373,278.704,21.88,69.633,0.049,0.573
45411,278.862,21.87,69.741,0.049,0.574
45449,279.019,21.87,69.847,0.049,0.575
45487,279.173,21.87,69.95,0.049,0.576
45525,279.344,21.87,70.067,0.049,0.577
45563,279.503,21.87,70.176,0.049,0.578
45601,279.658,21.86,70.28,0.049,0.578
45639,279.82,21.86,70.391,0.049,0.579
45677,279.981,21.86,70.5,0.049,0.58
45715,280.143,21.86,70.613,0.049,0.581
45753,280.298,21.85,70.719,0.049,0.582
45791,280.454,21.85,70.826,0.049,0.583
45829,280.607,21.85,70.93,0.049,0.584
45867,280.766,21.85,71.037,0.049,0.585
45905,280.926,21.84,71.15,0.049,0.586
45943,281.086,21.83,71.26,0.049,0.587
45981,281.242,21.83,71.367,0.049,0.587
46019,281.402,21.83,71.478,0.049,0.588
46057,281.558,21.82,71.585,0.048,0.589
46095,281.715,21.82,71.693,0.048,0.59
46133,281.876,21.81,71.804,0.048,0.591
46171,282.033,21.81,71.912,0.048,0.592
46209,282.198,21.81,72.028,0.048,0.593
46247,282.354,21.8,72.136,0.048,0.594
46285,282.51,21.8,72.244,0.048,0.595
46323,282.67,21.8,72.356,0.048,0.596
46361,282.83,21.8,72.467,0.048,0.596
46399,282.989,21.79,72.576,0.048,0.597
46437,283.148,21.78,72.687,0.048,0.598
46475,283.306,21.78,72.796,0.048,0.599
46513,283.467,21.78,72.911,0.048,0.6
46551,283.618,21.77,73.017,0.048,0.601
46589,283.778,21.77,73.129,0.048,0.602
46627,283.93,21.76,73.236,0.048,0.603
46665,284.09,21.76,73.348,0.048,0.604
46703,284.246,21.76,73.457,0.048,0.605
46741,284.402,21.75,73.567,0.048,0.605
46779,284.557,21.74,73.674,0.048,0.606
46817,284.714,21.74,73.787,0.048,0.607
46855,284.878,21.74,73.903,0.048,0.608
46893,285.049,21.74,74.021,0.048,0.609
46931,285.196,21.73,74.126,0.048,0.61
46969,285.353,21.72,74.236,0.048,0.611
47007,285.515,21.72,74.352,0.048,0.612
47045,285.67,21.72,74.463,0.048,0.613
47083,285.826,21.71,74.574,0.048,0.614
47121,285.982,21.71,74.685,0.048,0.615
47159,286.142,21.7,74.798,0.048,0.616
47197,286.298,21.7,74.91,0.048,0.617
47235,286.458,21.7,75.024,0.048,0.617
47273,286.62,21.69,75.138,0.048,0.618
47311,286.776,21.69,75.249,0.048,0.619
47349,286.932,21.68,75.361,0.048,0.62
47387,287.09,21.67,75.475,0.048,0.621
47425,287.246,19.58,75.587,0.044,0.622
47463,287.402,20.07,75.702,0.045,0.623
47501,287.558,20.7,75.816,0.046,0.624
47539,287.714,21.23,75.929,0.047,0.625
47577,287.882,21.44,76.051,0.048,0.626
47615,288.036,21.52,76.161,0.048,0.627
47653,288.189,21.54,76.27,0.048,0.628
47691,288.346,21.55,76.383,0.048,0.629
47729,288.508,21.54,76.502,0.048,0.63
47767,288.662,21.53,76.615,0.048,0.631
47805,288.822,21.52,76.731,0.048,0.632
47843,288.978,21.52,76.844,0.048,0.632
47881,289.138,21.52,76.96,0.048,0.633
47919,289.294,21.51,77.074,0.048,0.634
47957,289.454,21.5,77.19,0.048,0.635
47995,289.61,21.49,77.304,0.048,0.636
48033,289.765,21.48,77.415,0.048,0.637
48071,289.93,21.48,77.538,0.048,0.638
48109,290.093,21.47,77.655,0.048,0.639
48147,290.249,21.46,77.772,0.048,0.64
48185,290.412,21.46,77.889,0.048,0.641
48223,290.566,21.45,78.004,0.048,0.642
48261,290.736,21.44,78.127,0.048,0.643
48299,290.894,21.44,78.245,0.048,0.644
48337,291.047,21.43,78.357,0.048,0.645
48375,291.206,21.43,78.474,0.048,0.646
48413,291.361,21.42,78.587,0.048,0.647
48451,291.514,21.41,78.702,0.048,0.648
48489,291.676,21.41,78.82,0.048,0.649
48527,291.834,21.4,78.938,0.048,0.65
48565,291.99,21.4,79.054,0.048,0.651
48603,292.146,21.39,79.17,0.048,0.652
48641,292.302,21.38,79.285,0.048,0.653
48679,292.462,21.38,79.404,0.048,0.654
48717,292.62,21.38,79.52,0.048,0.654
48755,292.778,21.37,79.639,0.047,0.655
48793,292.938,21.36,79.759,0.047,0.656
48831,293.09,21.36,79.872,0.047,0.657
48869,293.248,21.35,79.989,0.047,0.658
48873,293.262,21.35,80.001,0.047,0.658