File: Old Beam/Load Beam 2.3.csv
No.,Time,Load,Disp,Strength,Strain
,[sec],[kN],[mm],[kN/mm²],[%]
1,0,0,0,0,0
4,0.307,0.31,0.016,0.001,0
7,0.995,0.32,0.019,0.001,0
10,1.475,0.33,0.021,0.001,0
13,1.873,0.34,0.023,0.001,0
16,2.152,0.36,0.024,0.001,0
19,2.387,0.37,0.026,0.001,0
22,2.683,0.38,0.028,0.001,0
25,2.966,0.39,0.03,0.001,0
28,3.216,0.4,0.031,0.001,0
31,3.391,0.41,0.033,0.001,0
34,3.603,0.43,0.035,0.001,0
37,3.835,0.44,0.037,0.001,0
40,4.058,0.45,0.039,0.001,0
43,4.227,0.47,0.04,0.001,0
46,4.549,0.49,0.043,0.001,0
49,4.841,0.51,0.046,0.001,0
52,5.107,0.53,0.049,0.001,0
55,5.425,0.55,0.053,0.001,0
58,5.749,0.57,0.056,0.001,0
61,6.015,0.6,0.06,0.001,0
64,6.339,0.62,0.064,0.001,0.001
67,6.649,0.65,0.068,0.001,0.001
70,6.934,0.68,0.071,0.002,0.001
73,7.239,0.7,0.076,0.002,0.001
76,7.522,0.73,0.08,0.002,0.001
79,7.863,0.76,0.085,0.002,0.001
82,8.131,0.79,0.089,0.002,0.001
85,8.45,0.82,0.094,0.002,0.001
88,8.707,0.85,0.098,0.002,0.001
91,9.014,0.88,0.103,0.002,0.001
94,9.317,0.92,0.108,0.002,0.001
97,9.613,0.94,0.113,0.002,0.001
100,9.949,0.97,0.118,0.002,0.001
103,10.237,1,0.124,0.002,0.001
106,10.511,1.04,0.129,0.002,0.001
109,10.806,1.08,0.134,0.002,0.001
112,11.154,1.12,0.141,0.002,0.001
115,11.417,1.16,0.146,0.003,0.001
118,11.709,1.21,0.151,0.003,0.001
121,12.026,1.25,0.158,0.003,0.001
124,12.308,1.3,0.163,0.003,0.001
127,12.621,1.34,0.17,0.003,0.001
130,12.911,1.39,0.176,0.003,0.001
133,13.246,1.45,0.183,0.003,0.002
136,13.535,1.49,0.189,0.003,0.002
139,13.817,1.54,0.195,0.003,0.002
142,14.138,1.59,0.201,0.004,0.002
145,14.41,1.64,0.208,0.004,0.002
148,14.733,1.69,0.215,0.004,0.002
151,15.038,1.75,0.221,0.004,0.002
154,15.31,1.79,0.228,0.004,0.002
157,15.614,1.85,0.234,0.004,0.002
160,15.923,1.9,0.242,0.004,0.002
163,16.227,1.95,0.249,0.004,0.002
166,16.521,2.01,0.255,0.004,0.002
169,16.818,2.06,0.263,0.005,0.002
172,17.114,2.11,0.27,0.005,0.002
175,17.406,2.17,0.277,0.005,0.002
178,17.711,2.23,0.284,0.005,0.002
181,18.022,2.28,0.292,0.005,0.002
184,18.305,2.34,0.298,0.005,0.002
187,18.615,2.4,0.306,0.005,0.003
190,18.907,2.45,0.314,0.005,0.003
193,19.224,2.51,0.322,0.006,0.003
196,19.505,2.57,0.329,0.006,0.003
199,19.814,2.63,0.337,0.006,0.003
202,20.126,2.69,0.345,0.006,0.003
205,20.435,2.75,0.353,0.006,0.003
208,20.703,2.81,0.36,0.006,0.003
211,21.007,2.87,0.368,0.006,0.003
214,21.312,2.93,0.376,0.007,0.003
217,21.602,3,0.383,0.007,0.003
220,21.914,3.06,0.391,0.007,0.003
223,22.214,3.12,0.4,0.007,0.003
226,22.51,3.19,0.408,0.007,0.003
229,22.806,3.25,0.416,0.007,0.003
232,23.129,3.32,0.424,0.007,0.003
235,23.414,3.38,0.432,0.008,0.004
238,23.71,3.44,0.44,0.008,0.004
241,24.01,3.5,0.449,0.008,0.004
244,24.334,3.56,0.458,0.008,0.004
247,24.62,3.62,0.466,0.008,0.004
250,24.902,3.68,0.474,0.008,0.004
253,25.222,3.74,0.483,0.008,0.004
256,25.503,3.8,0.491,0.008,0.004
259,25.82,3.86,0.5,0.009,0.004
262,26.131,3.92,0.509,0.009,0.004
265,26.406,3.98,0.517,0.009,0.004
268,26.714,4.04,0.526,0.009,0.004
271,27.005,4.11,0.534,0.009,0.004
274,27.326,4.17,0.544,0.009,0.004
277,27.62,4.24,0.552,0.009,0.005
280,27.905,4.3,0.561,0.01,0.005
283,28.202,4.36,0.57,0.01,0.005
286,28.508,4.42,0.579,0.01,0.005
289,28.805,4.48,0.588,0.01,0.005
292,29.107,4.54,0.597,0.01,0.005
295,29.414,4.6,0.606,0.01,0.005
298,29.714,4.66,0.615,0.01,0.005
301,30.01,4.71,0.625,0.01,0.005
304,30.302,4.77,0.634,0.011,0.005
307,30.606,4.84,0.643,0.011,0.005
310,30.91,4.9,0.653,0.011,0.005
313,31.226,4.97,0.663,0.011,0.005
316,31.506,5.03,0.671,0.011,0.006
319,31.822,5.09,0.682,0.011,0.006
322,32.105,5.16,0.69,0.011,0.006
325,32.416,5.23,0.7,0.012,0.006
328,32.718,5.3,0.71,0.012,0.006
331,33.012,5.37,0.72,0.012,0.006
334,33.32,5.44,0.73,0.012,0.006
337,33.626,5.52,0.74,0.012,0.006
340,33.905,5.59,0.749,0.012,0.006
343,34.214,5.66,0.759,0.013,0.006
346,34.522,5.74,0.769,0.013,0.006
349,34.806,5.82,0.778,0.013,0.006
352,35.106,5.89,0.788,0.013,0.006
355,35.41,5.97,0.798,0.013,0.007
358,35.718,6.05,0.808,0.013,0.007
361,36.01,6.13,0.817,0.014,0.007
364,36.314,6.21,0.827,0.014,0.007
367,36.606,6.28,0.837,0.014,0.007
370,36.91,6.37,0.847,0.014,0.007
373,37.205,6.45,0.856,0.014,0.007
376,37.5,6.53,0.866,0.015,0.007
379,37.8,6.61,0.876,0.015,0.007
382,38.106,6.69,0.886,0.015,0.007
385,38.415,6.77,0.896,0.015,0.007
388,38.718,6.85,0.906,0.015,0.007
391,39.018,6.94,0.915,0.015,0.008
394,39.304,7.01,0.925,0.016,0.008
397,39.608,7.1,0.935,0.016,0.008
400,39.904,7.18,0.944,0.016,0.008
403,40.204,7.26,0.954,0.016,0.008
406,40.504,7.34,0.964,0.016,0.008
409,40.801,7.42,0.974,0.016,0.008
412,41.11,7.5,0.984,0.017,0.008
415,41.413,7.58,0.994,0.017,0.008
418,41.718,7.67,1.003,0.017,0.008
421,42.018,7.75,1.013,0.017,0.008
424,42.306,7.82,1.023,0.017,0.008
427,42.61,7.9,1.033,0.018,0.009
430,42.914,7.99,1.042,0.018,0.009
433,43.212,8.07,1.052,0.018,0.009
436,43.501,8.14,1.062,0.018,0.009
439,43.805,8.22,1.072,0.018,0.009
442,44.113,8.31,1.082,0.018,0.009
445,44.416,8.39,1.091,0.019,0.009
448,44.716,8.47,1.101,0.019,0.009
451,45.001,8.54,1.111,0.019,0.009
454,45.309,8.62,1.121,0.019,0.009
457,45.613,8.7,1.13,0.019,0.009
460,45.922,8.79,1.141,0.02,0.009
463,46.217,8.87,1.15,0.02,0.009
466,46.502,8.94,1.16,0.02,0.01
469,46.811,9.02,1.17,0.02,0.01
472,47.109,9.1,1.179,0.02,0.01
475,47.405,9.19,1.189,0.02,0.01
478,47.709,9.27,1.199,0.021,0.01
481,48.006,9.34,1.209,0.021,0.01
484,48.308,9.43,1.218,0.021,0.01
487,48.607,9.51,1.228,0.021,0.01
490,48.905,9.59,1.238,0.021,0.01
493,49.201,9.67,1.248,0.021,0.01
496,49.506,9.75,1.258,0.022,0.01
499,49.806,9.83,1.267,0.022,0.01
502,50.112,9.91,1.277,0.022,0.011
505,50.409,9.99,1.287,0.022,0.011
508,50.702,10.06,1.297,0.022,0.011
511,51.009,10.15,1.307,0.023,0.011
514,51.309,10.23,1.316,0.023,0.011
517,51.61,10.31,1.326,0.023,0.011
520,51.901,10.38,1.336,0.023,0.011
523,52.212,10.47,1.346,0.023,0.011
526,52.511,10.55,1.355,0.023,0.011
529,52.81,10.63,1.365,0.024,0.011
532,53.101,10.71,1.375,0.024,0.011
535,53.407,10.79,1.385,0.024,0.011
538,53.701,10.87,1.394,0.024,0.011
541,54,10.94,1.404,0.024,0.012
544,54.313,11.03,1.414,0.025,0.012
547,54.605,11.1,1.424,0.025,0.012
550,54.913,11.18,1.434,0.025,0.012
553,55.209,11.26,1.443,0.025,0.012
556,55.526,11.33,1.454,0.025,0.012
559,55.8,11.4,1.462,0.025,0.012
562,56.105,11.48,1.473,0.026,0.012
565,56.413,11.56,1.483,0.026,0.012
568,56.719,11.63,1.493,0.026,0.012
571,57.011,11.71,1.502,0.026,0.012
574,57.33,11.79,1.513,0.026,0.012
577,57.603,11.85,1.522,0.026,0.013
580,57.901,11.93,1.532,0.027,0.013
583,58.205,12,1.542,0.027,0.013
586,58.511,12.08,1.552,0.027,0.013
589,58.801,12.14,1.561,0.027,0.013
592,59.115,12.22,1.572,0.027,0.013
595,59.413,12.27,1.582,0.027,0.013
598,59.712,12.32,1.592,0.027,0.013
601,60.005,12.38,1.602,0.028,0.013
604,60.301,12.43,1.611,0.028,0.013
607,60.601,12.5,1.622,0.028,0.013
610,60.913,12.56,1.633,0.028,0.013
613,61.203,12.62,1.642,0.028,0.014
616,61.5,12.68,1.653,0.028,0.014
619,61.809,12.73,1.664,0.028,0.014
622,62.101,12.79,1.674,0.028,0.014
625,62.409,12.84,1.685,0.029,0.014
628,62.7,12.9,1.695,0.029,0.014
631,63.009,12.96,1.706,0.029,0.014
634,63.305,13.01,1.717,0.029,0.014
637,63.609,13.07,1.728,0.029,0.014
640,63.913,13.13,1.739,0.029,0.014
643,64.217,13.18,1.75,0.029,0.014
646,64.508,13.23,1.76,0.029,0.014
649,64.815,13.29,1.772,0.03,0.015
652,65.111,13.31,1.783,0.03,0.015
655,65.401,13.33,1.794,0.03,0.015
658,65.717,13.33,1.806,0.03,0.015
661,66,13.35,1.817,0.03,0.015
664,66.305,13.39,1.829,0.03,0.015
667,66.605,13.41,1.841,0.03,0.015
670,66.904,13.44,1.852,0.03,0.015
673,67.203,13.46,1.865,0.03,0.015
676,67.517,13.49,1.878,0.03,0.015
679,67.805,13.53,1.89,0.03,0.016
682,68.103,13.57,1.902,0.03,0.016
685,68.421,13.57,1.916,0.03,0.016
688,68.721,13.56,1.929,0.03,0.016
691,69.005,13.59,1.941,0.03,0.016
694,69.313,13.62,1.955,0.03,0.016
697,69.601,13.65,1.968,0.03,0.016
700,69.913,13.68,1.982,0.03,0.016
703,70.221,13.71,1.996,0.03,0.016
706,70.501,13.73,2.009,0.031,0.017
709,70.804,13.76,2.023,0.031,0.017
712,71.103,13.78,2.037,0.031,0.017
715,71.417,13.81,2.052,0.031,0.017
718,71.709,13.83,2.066,0.031,0.017
721,72,13.84,2.08,0.031,0.017
724,72.305,13.86,2.095,0.031,0.017
727,72.604,13.88,2.11,0.031,0.017
730,72.905,13.91,2.125,0.031,0.017
733,73.201,13.94,2.14,0.031,0.018
736,73.513,13.96,2.156,0.031,0.018
739,73.807,13.99,2.171,0.031,0.018
742,74.114,14,2.187,0.031,0.018
745,74.407,14.03,2.202,0.031,0.018
748,74.717,14.04,2.219,0.031,0.018
751,75.019,14.06,2.235,0.031,0.018
754,75.311,14.08,2.251,0.031,0.019
757,75.6,14.09,2.266,0.031,0.019
760,75.909,14.1,2.284,0.031,0.019
763,76.215,14.1,2.301,0.031,0.019
766,76.509,14.11,2.318,0.031,0.019
769,76.808,14.11,2.335,0.031,0.019
772,77.116,14.1,2.352,0.031,0.019
775,77.406,14.08,2.37,0.031,0.02
778,77.705,14.08,2.388,0.031,0.02
781,78.001,14.07,2.406,0.031,0.02
784,78.313,14.07,2.425,0.031,0.02
787,78.6,14.07,2.443,0.031,0.02
790,78.905,14.08,2.462,0.031,0.02
793,79.204,14.09,2.48,0.031,0.02
796,79.5,14.09,2.5,0.031,0.021
799,79.808,14.09,2.52,0.031,0.021
802,80.113,14.07,2.54,0.031,0.021
805,80.413,14.06,2.56,0.031,0.021
808,80.713,14.06,2.58,0.031,0.021
811,81.006,14.06,2.6,0.031,0.021
814,81.312,14.06,2.621,0.031,0.022
817,81.603,14.06,2.641,0.031,0.022
820,81.901,14.06,2.662,0.031,0.022
823,82.209,14.06,2.684,0.031,0.022
826,82.504,14.06,2.705,0.031,0.022
829,82.809,14.07,2.727,0.031,0.022
832,83.111,14.07,2.749,0.031,0.023
835,83.408,14.07,2.771,0.031,0.023
838,83.7,14.07,2.793,0.031,0.023
841,84.008,14.07,2.816,0.031,0.023
844,84.314,14.07,2.839,0.031,0.023
847,84.609,14.07,2.862,0.031,0.024
850,84.908,14.06,2.885,0.031,0.024
853,85.2,14.06,2.908,0.031,0.024
856,85.505,14.07,2.932,0.031,0.024
859,85.8,14.07,2.955,0.031,0.024
862,86.104,14.07,2.98,0.031,0.025
865,86.4,14.07,3.003,0.031,0.025
868,86.704,14.06,3.028,0.031,0.025
871,87.008,14.05,3.054,0.031,0.025
874,87.308,14.04,3.079,0.031,0.025
877,87.6,14.01,3.104,0.031,0.026
880,87.908,14.01,3.13,0.031,0.026
883,88.21,14,3.156,0.031,0.026
886,88.509,14,3.182,0.031,0.026
889,88.807,14.01,3.208,0.031,0.026
892,89.108,14.01,3.235,0.031,0.027
895,89.402,14.01,3.261,0.031,0.027
898,89.7,14.01,3.288,0.031,0.027
901,90.008,14,3.315,0.031,0.027
904,90.305,14,3.343,0.031,0.028
907,90.608,14,3.371,0.031,0.028
910,90.907,14,3.398,0.031,0.028
913,91.206,14,3.427,0.031,0.028
916,91.5,14,3.455,0.031,0.028
919,91.801,14.01,3.483,0.031,0.029
922,92.11,14.01,3.513,0.031,0.029
925,92.404,14.02,3.542,0.031,0.029
928,92.704,14.02,3.571,0.031,0.029
931,93.003,14.02,3.6,0.031,0.03
934,93.3,14.02,3.63,0.031,0.03
937,93.612,14.03,3.661,0.031,0.03
940,93.9,14.04,3.69,0.031,0.03
943,94.21,14.04,3.721,0.031,0.031
946,94.502,14.05,3.751,0.031,0.031
949,94.802,14.05,3.781,0.031,0.031
952,95.106,14.05,3.813,0.031,0.031
955,95.4,14.06,3.843,0.031,0.032
958,95.711,14.07,3.877,0.031,0.032
961,96.008,14.07,3.908,0.031,0.032
964,96.302,14.07,3.939,0.031,0.032
967,96.606,14.07,3.972,0.031,0.033
970,96.904,14.09,4.004,0.031,0.033
973,97.21,14.1,4.037,0.031,0.033
976,97.5,14.11,4.069,0.031,0.033
979,97.8,14.12,4.102,0.031,0.034
982,98.104,14.13,4.136,0.031,0.034
985,98.404,14.14,4.169,0.031,0.034
988,98.704,14.15,4.203,0.031,0.035
991,99.003,14.16,4.236,0.031,0.035
994,99.304,14.18,4.271,0.032,0.035
997,99.603,14.19,4.305,0.032,0.035
1000,99.9,14.2,4.339,0.032,0.036
1003,100.202,14.22,4.374,0.032,0.036
1006,100.504,14.23,4.409,0.032,0.036
1009,100.803,14.24,4.444,0.032,0.037
1012,101.1,14.26,4.479,0.032,0.037
1015,101.404,14.27,4.515,0.032,0.037
1018,101.708,14.28,4.551,0.032,0.037
1021,102.002,14.29,4.586,0.032,0.038
1024,102.31,14.3,4.623,0.032,0.038
1027,102.604,14.31,4.659,0.032,0.038
1030,102.9,14.32,4.695,0.032,0.039
1033,103.2,14.34,4.732,0.032,0.039
1036,103.5,14.36,4.769,0.032,0.039
1039,103.8,14.37,4.806,0.032,0.04
1042,104.106,14.39,4.844,0.032,0.04
1045,104.399,14.41,4.881,0.032,0.04
1048,104.699,14.42,4.919,0.032,0.04
1051,105.004,14.44,4.957,0.032,0.041
1054,105.3,14.46,4.995,0.032,0.041
1057,105.604,14.47,5.034,0.032,0.041
1060,105.899,14.49,5.072,0.032,0.042
1063,106.206,14.5,5.111,0.032,0.042
1066,106.504,14.52,5.15,0.032,0.042
1069,106.8,14.54,5.189,0.032,0.043
1072,107.1,14.55,5.228,0.032,0.043
1075,107.4,14.56,5.268,0.032,0.043
1078,107.704,14.58,5.308,0.032,0.044
1081,108.003,14.6,5.348,0.032,0.044
1084,108.301,14.61,5.388,0.032,0.044
1087,108.6,14.63,5.428,0.033,0.045
1090,108.9,14.65,5.469,0.033,0.045
1093,109.206,14.67,5.51,0.033,0.045
1096,109.506,14.68,5.551,0.033,0.046
1099,109.799,14.7,5.591,0.033,0.046
1102,110.105,14.71,5.634,0.033,0.046
1105,110.4,14.73,5.675,0.033,0.047
1108,110.701,14.75,5.717,0.033,0.047
1111,110.999,14.76,5.759,0.033,0.047
1114,111.3,14.77,5.801,0.033,0.048
1117,111.605,14.78,5.844,0.033,0.048
1120,111.904,14.8,5.887,0.033,0.048
1123,112.2,14.82,5.929,0.033,0.049
1126,112.506,14.82,5.973,0.033,0.049
1129,112.799,14.82,6.016,0.033,0.05
1132,113.106,14.84,6.06,0.033,0.05
1135,113.4,14.86,6.103,0.033,0.05
1138,113.699,14.87,6.147,0.033,0.051
1141,113.999,14.9,6.191,0.033,0.051
1144,114.3,14.92,6.236,0.033,0.051
1147,114.606,14.94,6.281,0.033,0.052
1150,114.906,14.96,6.326,0.033,0.052
1153,115.205,14.98,6.371,0.033,0.052
1156,115.506,15,6.416,0.033,0.053
1159,115.799,15.01,6.461,0.033,0.053
1162,116.104,15.03,6.507,0.033,0.054
1165,116.404,15.04,6.553,0.033,0.054
1168,116.704,15.06,6.599,0.033,0.054
1171,117.007,15.07,6.645,0.033,0.055
1174,117.303,15.09,6.692,0.034,0.055
1177,117.599,15.11,6.737,0.034,0.055
1180,117.899,15.13,6.785,0.034,0.056
1183,118.199,15.14,6.832,0.034,0.056
1186,118.503,15.17,6.88,0.034,0.057
1189,118.799,15.18,6.927,0.034,0.057
1192,119.109,15.19,6.976,0.034,0.057
1195,119.401,15.2,7.023,0.034,0.058
1198,119.699,15.22,7.071,0.034,0.058
1201,120.003,15.24,7.12,0.034,0.059
1204,120.299,15.25,7.168,0.034,0.059
1207,120.599,15.27,7.217,0.034,0.059
1210,120.899,15.28,7.266,0.034,0.06
1213,121.199,15.3,7.315,0.034,0.06
1216,121.505,15.32,7.365,0.034,0.061
1219,121.803,15.33,7.415,0.034,0.061
1222,122.103,15.35,7.465,0.034,0.061
1225,122.403,15.36,7.515,0.034,0.062
1228,122.699,15.37,7.565,0.034,0.062
1231,123.006,15.39,7.616,0.034,0.063
1234,123.299,15.41,7.666,0.034,0.063
1237,123.6,15.42,7.717,0.034,0.064
1240,123.903,15.43,7.769,0.034,0.064
1243,124.211,15.44,7.822,0.034,0.064
1246,124.499,15.45,7.872,0.034,0.065
1249,124.799,15.46,7.924,0.034,0.065
1252,125.099,15.49,7.976,0.034,0.066
1255,125.403,15.5,8.029,0.034,0.066
1258,125.701,15.52,8.081,0.034,0.067
1261,126.001,15.53,8.134,0.035,0.067
1264,126.301,15.55,8.187,0.035,0.067
1267,126.599,15.57,8.239,0.035,0.068
1270,126.899,15.58,8.294,0.035,0.068
1273,127.203,15.6,8.348,0.035,0.069
1276,127.501,15.61,8.401,0.035,0.069
1279,127.803,15.63,8.456,0.035,0.07
1282,128.099,15.65,8.51,0.035,0.07
1285,128.402,15.66,8.565,0.035,0.07
1288,128.699,15.66,8.619,0.035,0.071
1291,129.003,15.67,8.675,0.035,0.071
1294,129.299,15.67,8.73,0.035,0.072
1297,129.599,15.69,8.785,0.035,0.072
1300,129.9,15.72,8.841,0.035,0.073
1303,130.199,15.74,8.897,0.035,0.073
1306,130.503,15.75,8.954,0.035,0.074
1309,130.799,15.77,9.01,0.035,0.074
1312,131.103,15.79,9.067,0.035,0.075
1315,131.403,15.8,9.124,0.035,0.075
1318,131.703,15.8,9.18,0.035,0.076
1321,132.002,15.81,9.239,0.035,0.076
1324,132.303,15.83,9.296,0.035,0.077
1327,132.603,15.85,9.354,0.035,0.077
1330,132.903,15.86,9.412,0.035,0.077
1333,133.201,15.88,9.47,0.035,0.078
1336,133.499,15.89,9.528,0.035,0.078
1339,133.799,15.91,9.587,0.035,0.079
1342,134.102,15.93,9.647,0.035,0.079
1345,134.399,15.94,9.705,0.035,0.08
1348,134.709,15.95,9.766,0.035,0.08
1351,135.005,15.96,9.825,0.035,0.081
1354,135.302,15.98,9.884,0.036,0.081
1357,135.603,15.99,9.945,0.036,0.082
1360,135.906,16.01,10.006,0.036,0.082
1363,136.202,16.03,10.066,0.036,0.083
1366,136.502,16.04,10.127,0.036,0.083
1369,136.803,16.06,10.188,0.036,0.084
1372,137.104,16.07,10.249,0.036,0.084
1375,137.405,16.08,10.311,0.036,0.085
1378,137.7,16.1,10.372,0.036,0.085
1381,138.003,16.12,10.435,0.036,0.086
1384,138.301,16.13,10.496,0.036,0.086
1387,138.601,16.14,10.559,0.036,0.087
1390,138.903,16.15,10.622,0.036,0.087
1393,139.203,16.17,10.685,0.036,0.088
1396,139.501,16.18,10.748,0.036,0.088
1399,139.806,16.19,10.812,0.036,0.089
1402,140.105,16.21,10.876,0.036,0.09
1405,140.409,16.23,10.94,0.036,0.09
1408,140.704,16.24,11.004,0.036,0.091
1411,141.005,16.24,11.068,0.036,0.091
1414,141.305,16.22,11.133,0.036,0.092
1417,141.604,16.23,11.198,0.036,0.092
1420,141.906,16.26,11.264,0.036,0.093
1423,142.205,16.27,11.328,0.036,0.093
1426,142.505,16.29,11.394,0.036,0.094
1429,142.803,16.31,11.46,0.036,0.094
1432,143.105,16.32,11.526,0.036,0.095
1435,143.406,16.32,11.593,0.036,0.095
1438,143.702,16.34,11.659,0.036,0.096
1441,144.003,16.35,11.726,0.036,0.097
1444,144.305,16.37,11.793,0.036,0.097
1447,144.601,16.38,11.86,0.036,0.098
1450,144.9,16.4,11.927,0.036,0.098
1453,145.204,16.41,11.996,0.036,0.099
1456,145.505,16.42,12.064,0.036,0.099
1459,145.805,16.43,12.132,0.037,0.1
1462,146.101,16.44,12.2,0.037,0.1
1465,146.402,16.46,12.27,0.037,0.101
1468,146.702,16.47,12.339,0.037,0.102
1471,147.005,16.48,12.408,0.037,0.102
1474,147.305,16.49,12.478,0.037,0.103
1477,147.605,16.51,12.548,0.037,0.103
1480,147.901,16.52,12.617,0.037,0.104
1483,148.205,16.53,12.688,0.037,0.104
1486,148.5,16.55,12.758,0.037,0.105
1489,148.805,16.56,12.83,0.037,0.106
1492,149.102,16.58,12.901,0.037,0.106
1495,149.403,16.59,12.972,0.037,0.107
1498,149.705,16.6,13.043,0.037,0.107
1501,150.005,16.61,13.115,0.037,0.108
1504,150.302,16.61,13.187,0.037,0.109
1507,150.604,16.63,13.26,0.037,0.109
1510,150.903,16.65,13.332,0.037,0.11
1513,151.206,16.67,13.406,0.037,0.11
1516,151.502,16.69,13.478,0.037,0.111
1519,151.801,16.7,13.55,0.037,0.112
1522,152.106,16.71,13.626,0.037,0.112
1525,152.405,16.73,13.699,0.037,0.113
1528,152.703,16.74,13.773,0.037,0.113
1531,153.003,16.76,13.847,0.037,0.114
1534,153.302,16.78,13.922,0.037,0.115
1537,153.601,16.8,13.995,0.037,0.115
1540,153.906,16.81,14.072,0.037,0.116
1543,154.202,16.82,14.147,0.037,0.116
1546,154.502,16.84,14.222,0.037,0.117
1549,154.81,16.86,14.3,0.037,0.118
1552,155.105,16.88,14.374,0.038,0.118
1555,155.405,16.9,14.45,0.038,0.119
1558,155.707,16.91,14.528,0.038,0.12
1561,156.002,16.93,14.603,0.038,0.12
1564,156.302,16.94,14.68,0.038,0.121
1567,156.601,16.96,14.756,0.038,0.121
1570,156.902,16.98,14.835,0.038,0.122
1573,157.205,17,14.912,0.038,0.123
1576,157.503,17.02,14.99,0.038,0.123
1579,157.804,17.03,15.069,0.038,0.124
1582,158.104,17.04,15.147,0.038,0.125
1585,158.404,17.06,15.226,0.038,0.125
1588,158.702,17.08,15.305,0.038,0.126
1591,159.005,17.09,15.384,0.038,0.127
1594,159.306,17.11,15.464,0.038,0.127
1597,159.602,17.13,15.543,0.038,0.128
1600,159.904,17.14,15.623,0.038,0.129
1603,160.202,17.16,15.703,0.038,0.129
1606,160.502,17.18,15.783,0.038,0.13
1609,160.802,17.2,15.864,0.038,0.131
1612,161.105,17.22,15.945,0.038,0.131
1615,161.402,17.24,16.026,0.038,0.132
1618,161.702,17.25,16.107,0.038,0.133
1621,162.006,17.27,16.19,0.038,0.133
1624,162.304,17.29,16.271,0.038,0.134
1627,162.602,17.31,16.353,0.038,0.135
1630,162.905,17.33,16.435,0.039,0.135
1633,163.205,17.35,16.518,0.039,0.136
1636,163.502,17.36,16.601,0.039,0.137
1639,163.808,17.38,16.685,0.039,0.137
1642,164.104,17.39,16.767,0.039,0.138
1645,164.401,17.4,16.851,0.039,0.139
1648,164.704,17.43,16.935,0.039,0.139
1651,165.002,17.45,17.019,0.039,0.14
1654,165.304,17.47,17.103,0.039,0.141
1657,165.606,17.48,17.189,0.039,0.141
1660,165.904,17.5,17.273,0.039,0.142
1663,166.202,17.52,17.358,0.039,0.143
1666,166.504,17.54,17.443,0.039,0.144
1669,166.802,17.55,17.529,0.039,0.144
1672,167.102,17.56,17.615,0.039,0.145
1675,167.406,17.58,17.702,0.039,0.146
1678,167.708,17.6,17.789,0.039,0.146
1681,168.007,17.62,17.875,0.039,0.147
1684,168.304,17.63,17.961,0.039,0.148
1687,168.604,17.66,18.048,0.039,0.149
1690,168.902,17.68,18.135,0.039,0.149
1693,169.206,17.7,18.224,0.039,0.15
1696,169.503,17.72,18.311,0.039,0.151
1699,169.803,17.73,18.399,0.039,0.151
1702,170.104,17.75,18.488,0.039,0.152
1705,170.404,17.77,18.576,0.039,0.153
1708,170.702,17.79,18.665,0.04,0.154
1711,171.005,17.81,18.755,0.04,0.154
1714,171.304,17.83,18.844,0.04,0.155
1717,171.604,17.85,18.933,0.04,0.156
1720,171.904,17.87,19.023,0.04,0.157
1723,172.202,17.88,19.113,0.04,0.157
1726,172.502,17.9,19.204,0.04,0.158
1729,172.804,17.92,19.294,0.04,0.159
1732,173.105,17.95,19.387,0.04,0.16
1735,173.404,17.97,19.476,0.04,0.16
1738,173.702,17.98,19.568,0.04,0.161
1741,174.01,18,19.662,0.04,0.162
1744,174.302,18.02,19.751,0.04,0.163
1747,174.605,18.04,19.845,0.04,0.163
1750,174.903,18.07,19.936,0.04,0.164
1753,175.203,18.09,20.029,0.04,0.165
1756,175.502,18.1,20.122,0.04,0.166
1759,175.804,18.13,20.215,0.04,0.166
1762,176.104,18.14,20.308,0.04,0.167
1765,176.402,18.16,20.402,0.04,0.168
1768,176.704,18.18,20.496,0.04,0.169
1771,177.005,18.2,20.591,0.04,0.169
1774,177.307,18.23,20.686,0.041,0.17
1777,177.605,18.25,20.78,0.041,0.171
1780,177.909,18.27,20.875,0.041,0.172
1783,178.202,18.29,20.969,0.041,0.173
1786,178.507,18.31,21.066,0.041,0.173
1789,178.805,18.33,21.162,0.041,0.174
1792,179.106,18.36,21.258,0.041,0.175
1795,179.403,18.38,21.353,0.041,0.176
1798,179.705,18.37,21.45,0.041,0.177
1801,180.015,18.39,21.55,0.041,0.177
1804,180.307,18.4,21.644,0.041,0.178
1807,180.603,18.42,21.74,0.041,0.179
1810,180.908,18.43,21.839,0.041,0.18
1813,181.208,18.45,21.937,0.041,0.181
1816,181.51,18.47,22.036,0.041,0.181
1819,181.805,18.48,22.134,0.041,0.182
1822,182.103,18.49,22.231,0.041,0.183
1825,182.405,18.51,22.331,0.041,0.184
1828,182.703,18.53,22.429,0.041,0.185
1831,183.008,18.54,22.53,0.041,0.185
1834,183.305,18.56,22.63,0.041,0.186
1837,183.605,18.57,22.73,0.041,0.187
1840,183.904,18.59,22.829,0.041,0.188
1843,184.208,18.61,22.93,0.041,0.189
1846,184.503,18.62,23.03,0.041,0.19
1849,184.805,18.63,23.132,0.041,0.19
1852,185.108,18.65,23.234,0.041,0.191
1855,185.407,18.66,23.335,0.041,0.192
1858,185.703,18.69,23.436,0.042,0.193
1861,186.005,18.71,23.539,0.042,0.194
1864,186.307,18.72,23.642,0.042,0.195
1867,186.607,18.74,23.745,0.042,0.195
1870,186.905,18.75,23.848,0.042,0.196
1873,187.207,18.77,23.951,0.042,0.197
1876,187.505,18.79,24.054,0.042,0.198
1879,187.808,18.8,24.158,0.042,0.199
1882,188.103,18.82,24.261,0.042,0.2
1885,188.403,18.84,24.365,0.042,0.201
1888,188.706,18.86,24.471,0.042,0.201
1891,189.005,18.88,24.576,0.042,0.202
1894,189.307,18.9,24.681,0.042,0.203
1897,189.607,18.91,24.786,0.042,0.204
1900,189.908,18.94,24.892,0.042,0.205
1903,190.203,18.95,24.997,0.042,0.206
1906,190.505,18.97,25.104,0.042,0.207
1909,190.805,18.96,25.211,0.042,0.207
1912,191.105,18.98,25.318,0.042,0.208
1915,191.405,18.99,25.425,0.042,0.209
1918,191.706,19.01,25.532,0.042,0.21
1921,192.005,19.02,25.64,0.042,0.211
1924,192.303,19.04,25.746,0.042,0.212
1927,192.603,19.06,25.854,0.042,0.213
1930,192.905,19.08,25.964,0.042,0.214
1933,193.205,19.1,26.073,0.042,0.215
1936,193.507,19.11,26.182,0.042,0.215
1939,193.805,19.13,26.291,0.043,0.216
1942,194.105,19.15,26.401,0.043,0.217
1945,194.403,19.17,26.509,0.043,0.218
1948,194.705,19.18,26.619,0.043,0.219
1951,195.007,19.19,26.731,0.043,0.22
1954,195.307,19.21,26.842,0.043,0.221
1957,195.607,19.23,26.953,0.043,0.222
1960,195.905,19.24,27.064,0.043,0.223
1963,196.204,19.25,27.174,0.043,0.224
1966,196.507,19.27,27.287,0.043,0.225
1969,196.807,19.29,27.399,0.043,0.226
1972,197.107,19.31,27.512,0.043,0.226
1975,197.405,19.32,27.624,0.043,0.227
1978,197.703,19.34,27.736,0.043,0.228
1981,198.005,19.35,27.85,0.043,0.229
1984,198.303,19.37,27.962,0.043,0.23
1987,198.604,19.39,28.078,0.043,0.231
1990,198.903,19.4,28.19,0.043,0.232
1993,199.205,19.42,28.306,0.043,0.233
1996,199.504,19.44,28.421,0.043,0.234
1999,199.803,19.46,28.534,0.043,0.235
2002,200.105,19.47,28.651,0.043,0.236
2005,200.405,19.49,28.766,0.043,0.237
2008,200.704,19.51,28.882,0.043,0.238
2011,201.005,19.53,28.998,0.043,0.239
2014,201.305,19.54,29.114,0.043,0.24
2017,201.607,19.56,29.231,0.043,0.241
2020,201.905,19.57,29.348,0.043,0.242
2023,202.208,19.59,29.466,0.044,0.243
2026,202.505,19.61,29.582,0.044,0.243
2029,202.807,19.62,29.7,0.044,0.244
2032,203.107,19.64,29.818,0.044,0.245
2035,203.407,19.66,29.936,0.044,0.246
2038,203.707,19.68,30.054,0.044,0.247
2041,204.005,19.69,30.173,0.044,0.248
2044,204.305,19.71,30.292,0.044,0.249
2047,204.607,19.73,30.412,0.044,0.25
2050,204.909,19.74,30.533,0.044,0.251
2053,205.205,19.76,30.651,0.044,0.252
2056,205.504,19.77,30.772,0.044,0.253
2059,205.804,19.79,30.892,0.044,0.254
2062,206.107,19.81,31.013,0.044,0.255
2065,206.405,19.83,31.134,0.044,0.256
2068,206.704,19.84,31.256,0.044,0.257
2071,207.007,19.86,31.377,0.044,0.258
2074,207.304,19.88,31.498,0.044,0.259
2077,207.605,19.89,31.622,0.044,0.26
2080,207.905,19.91,31.744,0.044,0.261
2083,208.204,19.92,31.865,0.044,0.262
2086,208.505,19.94,31.99,0.044,0.263
2089,208.805,19.96,32.113,0.044,0.264
2092,209.104,19.97,32.237,0.044,0.265
2095,209.405,19.99,32.361,0.044,0.266
2098,209.707,20.01,32.485,0.044,0.267
2101,210.015,20.02,32.613,0.044,0.268
2104,210.304,20.04,32.735,0.045,0.269
2107,210.604,20.05,32.86,0.045,0.27
2110,210.907,20.07,32.986,0.045,0.271
2113,211.204,20.09,33.111,0.045,0.273
2116,211.504,20.1,33.237,0.045,0.274
2119,211.804,20.12,33.364,0.045,0.275
2122,212.105,20.14,33.49,0.045,0.276
2125,212.407,20.15,33.617,0.045,0.277
2128,212.704,20.16,33.744,0.045,0.278
2131,213.004,20.18,33.872,0.045,0.279
2134,213.304,20.2,34,0.045,0.28
2137,213.607,20.21,34.128,0.045,0.281
2140,213.907,20.23,34.256,0.045,0.282
2143,214.204,20.24,34.385,0.045,0.283
2146,214.505,20.26,34.514,0.045,0.284
2149,214.804,20.27,34.643,0.045,0.285
2152,215.105,20.29,34.773,0.045,0.286
2155,215.404,20.31,34.903,0.045,0.287
2158,215.706,20.32,35.033,0.045,0.288
2161,216.006,20.33,35.163,0.045,0.289
2164,216.304,20.35,35.294,0.045,0.29
2167,216.607,20.37,35.425,0.045,0.292
2170,216.907,20.39,35.556,0.045,0.293
2173,217.205,20.39,35.688,0.045,0.294
2176,217.509,20.41,35.822,0.045,0.295
2179,217.805,20.43,35.952,0.045,0.296
2182,218.107,20.45,36.085,0.045,0.297
2185,218.405,20.46,36.218,0.045,0.298
2188,218.706,20.47,36.351,0.045,0.299
2191,219.008,20.49,36.486,0.046,0.3
2194,219.305,20.5,36.618,0.046,0.301
2197,219.605,20.52,36.752,0.046,0.302
2200,219.91,20.54,36.888,0.046,0.304
2203,220.208,20.56,37.023,0.046,0.305
2206,220.507,20.57,37.156,0.046,0.306
2209,220.808,20.58,37.293,0.046,0.307
2212,221.109,20.6,37.429,0.046,0.308
2215,221.408,20.62,37.565,0.046,0.309
2218,221.71,20.63,37.701,0.046,0.31
2221,222.008,20.64,37.838,0.046,0.311
2224,222.308,20.66,37.974,0.046,0.313
2227,222.605,20.68,38.11,0.046,0.314
2230,222.908,20.69,38.249,0.046,0.315
2233,223.208,20.7,38.386,0.046,0.316
2236,223.507,20.72,38.523,0.046,0.317
2239,223.809,20.73,38.663,0.046,0.318
2242,224.108,20.75,38.801,0.046,0.319
2245,224.408,20.77,38.94,0.046,0.32
2248,224.71,20.78,39.08,0.046,0.322
2251,225.006,20.79,39.217,0.046,0.323
2254,225.308,20.81,39.359,0.046,0.324
2257,225.606,20.83,39.497,0.046,0.325
2260,225.906,20.84,39.638,0.046,0.326
2263,226.208,20.85,39.78,0.046,0.327
2266,226.508,20.87,39.921,0.046,0.329
2269,226.811,20.88,40.063,0.046,0.33
2272,227.11,20.89,40.205,0.046,0.331
2275,227.408,20.91,40.347,0.046,0.332
2278,227.71,20.93,40.489,0.047,0.333
2281,228.006,20.94,40.63,0.047,0.334
2284,228.307,20.95,40.773,0.047,0.336
2287,228.61,20.96,40.918,0.047,0.337
2290,228.91,20.98,41.061,0.047,0.338
2293,229.206,20.99,41.203,0.047,0.339
2296,229.511,21,41.349,0.047,0.34
2299,229.807,21.02,41.494,0.047,0.342
2302,230.11,21.03,41.639,0.047,0.343
2305,230.406,21.04,41.782,0.047,0.344
2308,230.707,21.06,41.927,0.047,0.345
2311,231.008,21.07,42.075,0.047,0.346
2314,231.311,21.08,42.223,0.047,0.348
2317,231.605,21.1,42.366,0.047,0.349
2320,231.909,21.11,42.514,0.047,0.35
2323,232.206,21.12,42.66,0.047,0.351
2326,232.506,21.13,42.807,0.047,0.352
2329,232.808,21.15,42.957,0.047,0.354
2332,233.106,21.16,43.103,0.047,0.355
2335,233.41,21.17,43.253,0.047,0.356
2338,233.707,21.18,43.402,0.047,0.357
2341,234.008,21.2,43.551,0.047,0.358
2344,234.31,21.2,43.7,0.047,0.36
2347,234.61,21.22,43.85,0.047,0.361
2350,234.906,21.23,43.997,0.047,0.362
2353,235.209,21.24,44.15,0.047,0.363
2356,235.508,21.25,44.3,0.047,0.365
2359,235.808,21.27,44.451,0.047,0.366
2362,236.109,21.28,44.602,0.047,0.367
2365,236.408,21.29,44.754,0.047,0.368
2368,236.711,21.3,44.906,0.047,0.37
2371,237.007,21.31,45.058,0.047,0.371
2374,237.307,21.32,45.209,0.047,0.372
2377,237.607,21.33,45.362,0.047,0.373
2380,237.908,21.35,45.517,0.047,0.375
2383,238.206,21.35,45.668,0.047,0.376
2386,238.506,21.36,45.822,0.047,0.377
2389,238.809,21.38,45.978,0.048,0.378
2392,239.108,21.39,46.133,0.048,0.38
2395,239.408,21.39,46.288,0.048,0.381
2398,239.712,21.41,46.445,0.048,0.382
2401,240.016,21.42,46.603,0.048,0.384
2404,240.306,21.42,46.752,0.048,0.385
2407,240.611,21.43,46.913,0.048,0.386
2410,240.906,21.45,47.065,0.048,0.387
2413,241.206,21.44,47.222,0.048,0.389
2416,241.51,21.45,47.381,0.048,0.39
2419,241.806,21.47,47.537,0.048,0.391
2422,242.106,21.47,47.695,0.048,0.393
2425,242.407,21.48,47.855,0.048,0.394
2428,242.707,21.5,48.013,0.048,0.395
2431,243.006,21.5,48.17,0.048,0.396
2434,243.306,21.51,48.329,0.048,0.398
2437,243.608,21.52,48.491,0.048,0.399
2440,243.906,21.53,48.649,0.048,0.4
2443,244.207,21.53,48.809,0.048,0.402
2446,244.506,21.54,48.97,0.048,0.403
2449,244.807,21.55,49.133,0.048,0.404
2452,245.111,21.55,49.296,0.048,0.406
2455,245.409,21.56,49.456,0.048,0.407
2458,245.707,21.57,49.616,0.048,0.408
2461,246.006,21.58,49.778,0.048,0.41
2464,246.306,21.59,49.941,0.048,0.411
2467,246.607,21.6,50.104,0.048,0.412
2470,246.907,21.6,50.269,0.048,0.414
2473,247.207,21.61,50.433,0.048,0.415
2476,247.511,21.62,50.599,0.048,0.416
2479,247.806,21.62,50.759,0.048,0.418
2482,248.109,21.63,50.926,0.048,0.419
2485,248.407,21.64,51.091,0.048,0.421
2488,248.71,21.65,51.257,0.048,0.422
2491,249.006,21.66,51.42,0.048,0.423
2494,249.307,21.67,51.589,0.048,0.425
2497,249.608,21.67,51.755,0.048,0.426
2500,249.909,21.68,51.922,0.048,0.427
2503,250.208,21.69,52.089,0.048,0.429
2506,250.512,21.69,52.259,0.048,0.43
2509,250.807,21.7,52.424,0.048,0.431
2512,251.107,21.71,52.593,0.048,0.433
2515,251.409,21.71,52.761,0.048,0.434
2518,251.707,21.72,52.93,0.048,0.436
2521,252.007,21.73,53.099,0.048,0.437
2524,252.31,21.73,53.269,0.048,0.438
2527,252.607,21.74,53.439,0.048,0.44
2530,252.914,21.75,53.612,0.048,0.441
2533,253.207,21.75,53.78,0.048,0.443
2536,253.509,21.76,53.951,0.048,0.444
2539,253.807,21.76,54.122,0.048,0.445
2542,254.109,21.77,54.294,0.048,0.447
2545,254.415,21.78,54.471,0.048,0.448
2548,254.707,21.78,54.639,0.048,0.45
2551,255.009,21.79,54.811,0.048,0.451
2554,255.309,21.8,54.985,0.048,0.453
2557,255.607,21.8,55.158,0.048,0.454
2560,255.907,21.81,55.332,0.048,0.455
2563,256.207,21.82,55.506,0.048,0.457
2566,256.509,21.82,55.681,0.048,0.458
2569,256.808,21.83,55.856,0.049,0.46
2572,257.107,21.84,56.029,0.049,0.461
2575,257.41,21.84,56.207,0.049,0.463
2578,257.707,21.85,56.383,0.049,0.464
2581,258.007,21.86,56.559,0.049,0.466
2584,258.311,21.86,56.738,0.049,0.467
2587,258.609,21.87,56.913,0.049,0.468
2590,258.907,21.89,57.09,0.049,0.47
2593,259.207,21.89,57.268,0.049,0.471
2596,259.509,21.9,57.446,0.049,0.473
2599,259.809,21.91,57.625,0.049,0.474
2602,260.107,21.91,57.804,0.049,0.476
2605,260.409,21.92,57.983,0.049,0.477
2608,260.709,21.92,58.162,0.049,0.479
2611,261.009,21.93,58.342,0.049,0.48
2614,261.309,21.94,58.523,0.049,0.482
2617,261.609,21.94,58.703,0.049,0.483
2620,261.907,21.94,58.882,0.049,0.485
2623,262.209,21.95,59.066,0.049,0.486
2626,262.507,21.95,59.248,0.049,0.488
2629,262.809,21.95,59.43,0.049,0.489
2632,263.107,21.96,59.612,0.049,0.491
2635,263.413,21.96,59.798,0.049,0.492
2638,263.707,21.97,59.979,0.049,0.494
2641,264.011,21.97,60.165,0.049,0.495
2644,264.31,21.97,60.349,0.049,0.497
2647,264.607,21.98,60.531,0.049,0.498
2650,264.907,21.98,60.715,0.049,0.5
2653,265.209,21.98,60.9,0.049,0.501
2656,265.508,21.98,61.086,0.049,0.503
2659,265.81,21.98,61.274,0.049,0.504
2662,266.111,21.98,61.461,0.049,0.506
2665,266.413,21.98,61.647,0.049,0.507
2668,266.709,21.98,61.832,0.049,0.509
2671,267.008,21.99,62.019,0.049,0.51
2674,267.31,21.98,62.21,0.049,0.512
2677,267.613,21.98,62.398,0.049,0.514
2680,267.909,21.98,62.584,0.049,0.515
2683,268.211,21.98,62.775,0.049,0.517
2686,268.508,21.99,62.962,0.049,0.518
2689,268.81,21.98,63.154,0.049,0.52
2692,269.109,21.98,63.342,0.049,0.521
2695,269.412,21.98,63.535,0.049,0.523
2698,269.71,21.98,63.726,0.049,0.524
2701,270.017,21.98,63.92,0.049,0.526
2704,270.31,21.97,64.109,0.049,0.528
2707,270.615,21.97,64.304,0.049,0.529
2710,270.91,21.97,64.494,0.049,0.531
2713,271.211,21.97,64.686,0.049,0.532
2716,271.51,21.97,64.88,0.049,0.534
2719,271.812,21.97,65.073,0.049,0.536
2722,272.111,21.96,65.267,0.049,0.537
2725,272.409,21.96,65.459,0.049,0.539
2728,272.712,21.96,65.657,0.049,0.54
2731,273.011,21.96,65.852,0.049,0.542
2734,273.31,21.96,66.048,0.049,0.544
2737,273.613,21.95,66.244,0.049,0.545
2740,273.911,21.95,66.44,0.049,0.547
2743,274.209,21.95,66.634,0.049,0.548
2746,274.511,21.94,66.834,0.049,0.55
2749,274.81,21.94,67.032,0.049,0.552
2752,275.11,21.93,67.23,0.049,0.553
2755,275.41,21.93,67.428,0.049,0.555
2758,275.712,21.92,67.627,0.049,0.557
2761,276.008,21.92,67.824,0.049,0.558
2764,276.31,21.92,68.026,0.049,0.56
2767,276.61,21.91,68.226,0.049,0.562
2770,276.91,21.91,68.424,0.049,0.563
2773,277.209,21.9,68.625,0.049,0.565
2776,277.512,21.9,68.829,0.049,0.566
2779,277.812,21.89,69.031,0.049,0.568
2782,278.112,21.88,69.233,0.049,0.57
2785,278.41,21.86,69.435,0.049,0.571
2788,278.71,21.88,69.638,0.049,0.573
2791,279.013,21.87,69.842,0.049,0.575
2794,279.308,21.87,70.043,0.049,0.576
2797,279.611,21.86,70.249,0.049,0.578
2800,279.91,21.86,70.454,0.049,0.58
2803,280.209,21.85,70.656,0.049,0.582
2806,280.508,21.85,70.862,0.049,0.583
2809,280.809,21.84,71.068,0.049,0.585
2812,281.108,21.83,71.274,0.049,0.587
2815,281.408,21.83,71.48,0.049,0.588
2818,281.71,21.82,71.69,0.048,0.59
2821,282.008,21.81,71.895,0.048,0.592
2824,282.308,21.8,72.103,0.048,0.593
2827,282.61,21.8,72.314,0.048,0.595
2830,282.912,21.79,72.523,0.048,0.597
2833,283.212,21.78,72.732,0.048,0.599
2836,283.511,21.78,72.941,0.048,0.6
2839,283.81,21.76,73.152,0.048,0.602
2842,284.112,21.76,73.362,0.048,0.604
2845,284.409,21.75,73.57,0.048,0.606
2848,284.71,21.74,73.784,0.048,0.607
2851,285.01,21.74,73.996,0.048,0.609
2854,285.31,21.72,74.205,0.048,0.611
2857,285.611,21.72,74.42,0.048,0.613
2860,285.91,21.71,74.633,0.048,0.614
2863,286.212,21.7,74.847,0.048,0.616
2866,286.512,21.69,75.061,0.048,0.618
2869,286.81,21.68,75.275,0.048,0.62
2872,287.112,21.67,75.49,0.048,0.621
2875,287.41,20.11,75.707,0.045,0.623
2878,287.712,21.22,75.926,0.047,0.625
2881,288.012,21.52,76.143,0.048,0.627
2884,288.31,21.55,76.36,0.048,0.628
2887,288.61,21.54,76.577,0.048,0.63
2890,288.912,21.52,76.795,0.048,0.632
2893,289.21,21.51,77.013,0.048,0.634
2896,289.51,21.49,77.231,0.048,0.636
2899,289.809,21.48,77.447,0.048,0.637
2902,290.112,21.46,77.669,0.048,0.639
2905,290.412,21.46,77.889,0.048,0.641
2908,290.709,21.45,78.106,0.048,0.643
2911,291.009,21.43,78.33,0.048,0.645
2914,291.309,21.42,78.551,0.048,0.647
2917,291.61,21.41,78.773,0.048,0.648
2920,291.909,21.4,78.995,0.048,0.65
2923,292.209,21.39,79.217,0.048,0.652
2926,292.51,21.38,79.44,0.048,0.654
2929,292.814,21.36,79.666,0.047,0.656
2932,293.112,21.35,79.887,0.047,0.658
2933,293.212,21.35,79.962,0.047,0.658